package dayz.common.world.generation.structures;

import java.util.Random;

import net.minecraft.block.Block;
import net.minecraft.item.ItemDoor;
import net.minecraft.tileentity.TileEntity;
import net.minecraft.tileentity.TileEntityChest;
import net.minecraft.util.WeightedRandomChestContent;
import net.minecraft.world.World;
import dayz.common.blocks.Blocks;
import dayz.common.misc.ChatHandler;
import dayz.common.misc.LootManager;

public class StructureFort implements IStructure
{
    @Override
    public boolean generate(World world, Random rand, int xCoord, int yCoord, int zCoord)
    {
        int bID = 2;

        if (world.getBlockId(xCoord, yCoord, zCoord) != bID || world.getBlockId(xCoord, yCoord + 1, zCoord) != 0 || world.getBlockId(xCoord + 7, yCoord, zCoord) != bID || world.getBlockId(xCoord + 7, yCoord, zCoord + 7) != bID || world.getBlockId(xCoord, yCoord, zCoord + 7) != bID || world.getBlockId(xCoord + 7, yCoord + 1, zCoord) != 0 || world.getBlockId(xCoord + 7, yCoord + 1, zCoord + 7) != 0 || world.getBlockId(xCoord, yCoord + 1, zCoord + 7) != 0)
        {
            return false;
        }
        world.setBlock(xCoord + 1, yCoord + 0, zCoord + 5, Block.stoneBrick.blockID, rand.nextInt(3), 2);
        world.setBlock(xCoord + 1, yCoord + 0, zCoord + 4, Block.stoneBrick.blockID, rand.nextInt(3), 2);
        world.setBlock(xCoord + 1, yCoord + 0, zCoord + 3, Block.stoneBrick.blockID, rand.nextInt(3), 2);
        world.setBlock(xCoord + 1, yCoord + 0, zCoord + 2, Block.stoneBrick.blockID, rand.nextInt(3), 2);
        world.setBlock(xCoord + 1, yCoord + 0, zCoord + 1, Block.stoneBrick.blockID, rand.nextInt(3), 2);
        world.setBlock(xCoord + 2, yCoord + 0, zCoord + 5, Block.stoneBrick.blockID, rand.nextInt(3), 2);
        world.setBlock(xCoord + 2, yCoord + 0, zCoord + 4, Block.stoneBrick.blockID, rand.nextInt(3), 2);
        world.setBlock(xCoord + 2, yCoord + 0, zCoord + 3, Block.stoneBrick.blockID, rand.nextInt(3), 2);
        world.setBlock(xCoord + 2, yCoord + 0, zCoord + 2, Block.stoneBrick.blockID, rand.nextInt(3), 2);
        world.setBlock(xCoord + 2, yCoord + 0, zCoord + 1, Block.stoneBrick.blockID, rand.nextInt(3), 2);
        world.setBlock(xCoord + 3, yCoord + 0, zCoord + 5, Block.stoneBrick.blockID, rand.nextInt(3), 2);
        world.setBlock(xCoord + 3, yCoord + 0, zCoord + 4, Block.stoneBrick.blockID, rand.nextInt(3), 2);
        world.setBlock(xCoord + 3, yCoord + 0, zCoord + 3, Block.stoneBrick.blockID, rand.nextInt(3), 2);
        world.setBlock(xCoord + 3, yCoord + 0, zCoord + 2, Block.stoneBrick.blockID, rand.nextInt(3), 2);
        world.setBlock(xCoord + 3, yCoord + 0, zCoord + 1, Block.stoneBrick.blockID, rand.nextInt(3), 2);
        world.setBlock(xCoord + 4, yCoord + 0, zCoord + 5, Block.stoneBrick.blockID, rand.nextInt(3), 2);
        world.setBlock(xCoord + 4, yCoord + 0, zCoord + 4, Block.stoneBrick.blockID, rand.nextInt(3), 2);
        world.setBlock(xCoord + 4, yCoord + 0, zCoord + 3, Block.stoneBrick.blockID, rand.nextInt(3), 2);
        world.setBlock(xCoord + 4, yCoord + 0, zCoord + 2, Block.stoneBrick.blockID, rand.nextInt(3), 2);
        world.setBlock(xCoord + 4, yCoord + 0, zCoord + 1, Block.stoneBrick.blockID, rand.nextInt(3), 2);
        world.setBlock(xCoord + 5, yCoord + 0, zCoord + 5, Block.stoneBrick.blockID, rand.nextInt(3), 2);
        world.setBlock(xCoord + 5, yCoord + 0, zCoord + 4, Block.stoneBrick.blockID, rand.nextInt(3), 2);
        world.setBlock(xCoord + 5, yCoord + 0, zCoord + 3, Block.stoneBrick.blockID, rand.nextInt(3), 2);
        world.setBlock(xCoord + 5, yCoord + 0, zCoord + 2, Block.stoneBrick.blockID, rand.nextInt(3), 2);
        world.setBlock(xCoord + 5, yCoord + 0, zCoord + 1, Block.stoneBrick.blockID, rand.nextInt(3), 2);
        world.setBlock(xCoord + 1, yCoord + 1, zCoord + 5, Block.stoneBrick.blockID, rand.nextInt(3), 2);
        world.setBlock(xCoord + 1, yCoord + 1, zCoord + 4, Block.stoneBrick.blockID, rand.nextInt(3), 2);
        world.setBlock(xCoord + 1, yCoord + 1, zCoord + 3, Block.stoneBrick.blockID, rand.nextInt(3), 2);
        world.setBlock(xCoord + 1, yCoord + 1, zCoord + 2, Block.stoneBrick.blockID, rand.nextInt(3), 2);
        world.setBlock(xCoord + 1, yCoord + 1, zCoord + 1, Block.stoneBrick.blockID, rand.nextInt(3), 2);
        world.setBlock(xCoord + 2, yCoord + 1, zCoord + 5, Block.stoneBrick.blockID, rand.nextInt(3), 2);
        world.setBlock(xCoord + 2, yCoord + 1, zCoord + 4, Block.stoneBrick.blockID, rand.nextInt(3), 2);
        world.setBlock(xCoord + 2, yCoord + 1, zCoord + 3, Block.stoneBrick.blockID, rand.nextInt(3), 2);
        world.setBlock(xCoord + 2, yCoord + 1, zCoord + 2, Block.stoneBrick.blockID, rand.nextInt(3), 2);
        world.setBlock(xCoord + 2, yCoord + 1, zCoord + 1, Block.stoneBrick.blockID, rand.nextInt(3), 2);
        world.setBlock(xCoord + 3, yCoord + 1, zCoord + 5, Block.stoneBrick.blockID, rand.nextInt(3), 2);
        world.setBlock(xCoord + 3, yCoord + 1, zCoord + 4, Block.stoneBrick.blockID, rand.nextInt(3), 2);
        world.setBlockToAir(xCoord + 3, yCoord + 1, zCoord + 3);
        world.setBlock(xCoord + 3, yCoord + 1, zCoord + 2, Block.stoneBrick.blockID, rand.nextInt(3), 2);
        world.setBlock(xCoord + 3, yCoord + 1, zCoord + 1, Block.stoneBrick.blockID, rand.nextInt(3), 2);
        world.setBlock(xCoord + 4, yCoord + 1, zCoord + 5, Block.stoneBrick.blockID, rand.nextInt(3), 2);
        world.setBlock(xCoord + 4, yCoord + 1, zCoord + 4, Block.stoneSingleSlab.blockID, 5, 2);
        world.setBlockToAir(xCoord + 4, yCoord + 1, zCoord + 3);
        world.setBlock(xCoord + 4, yCoord + 1, zCoord + 2, Block.stoneBrick.blockID, rand.nextInt(3), 2);
        world.setBlock(xCoord + 4, yCoord + 1, zCoord + 1, Block.stoneBrick.blockID, rand.nextInt(3), 2);
        world.setBlock(xCoord + 5, yCoord + 1, zCoord + 5, Block.stoneBrick.blockID, rand.nextInt(3), 2);
        world.setBlock(xCoord + 5, yCoord + 1, zCoord + 4, Block.stoneBrick.blockID, rand.nextInt(3), 2);
        ItemDoor.placeDoorBlock(world, xCoord + 5, yCoord + 1, zCoord + 3, 0, Block.doorWood);
        world.setBlock(xCoord + 5, yCoord + 1, zCoord + 2, Block.stoneBrick.blockID, rand.nextInt(3), 2);
        world.setBlock(xCoord + 5, yCoord + 1, zCoord + 1, Block.stoneBrick.blockID, rand.nextInt(3), 2);
        world.setBlock(xCoord + 1, yCoord + 2, zCoord + 5, Block.stoneBrick.blockID, rand.nextInt(3), 2);
        world.setBlock(xCoord + 1, yCoord + 2, zCoord + 4, Block.stoneBrick.blockID, rand.nextInt(3), 2);
        world.setBlock(xCoord + 1, yCoord + 2, zCoord + 3, Block.stoneBrick.blockID, rand.nextInt(3), 2);
        world.setBlock(xCoord + 1, yCoord + 2, zCoord + 2, Block.stoneBrick.blockID, rand.nextInt(3), 2);
        world.setBlock(xCoord + 1, yCoord + 2, zCoord + 1, Block.stoneBrick.blockID, rand.nextInt(3), 2);
        world.setBlock(xCoord + 2, yCoord + 2, zCoord + 5, Block.stoneBrick.blockID, rand.nextInt(3), 2);
        world.setBlock(xCoord + 2, yCoord + 2, zCoord + 4, Block.stoneSingleSlab.blockID, 5, 2);
        world.setBlock(xCoord + 2, yCoord + 2, zCoord + 3, Block.stoneBrick.blockID, rand.nextInt(3), 2);
        world.setBlock(xCoord + 2, yCoord + 2, zCoord + 2, Block.stoneBrick.blockID, rand.nextInt(3), 2);
        world.setBlock(xCoord + 2, yCoord + 2, zCoord + 1, Block.stoneBrick.blockID, rand.nextInt(3), 2);
        world.setBlock(xCoord + 3, yCoord + 2, zCoord + 5, Block.stoneBrick.blockID, rand.nextInt(3), 2);
        world.setBlockToAir(xCoord + 3, yCoord + 2, zCoord + 4);
        world.setBlockToAir(xCoord + 3, yCoord + 2, zCoord + 3);
        world.setBlock(xCoord + 3, yCoord + 2, zCoord + 2, Block.stoneBrick.blockID, rand.nextInt(3), 2);
        world.setBlock(xCoord + 3, yCoord + 2, zCoord + 1, Block.stoneBrick.blockID, rand.nextInt(3), 2);
        world.setBlock(xCoord + 4, yCoord + 2, zCoord + 5, Block.stoneBrick.blockID, rand.nextInt(3), 2);
        world.setBlockToAir(xCoord + 4, yCoord + 2, zCoord + 4);
        world.setBlockToAir(xCoord + 4, yCoord + 2, zCoord + 3);
        world.setBlock(xCoord + 4, yCoord + 2, zCoord + 2, Block.stoneBrick.blockID, rand.nextInt(3), 2);
        world.setBlock(xCoord + 4, yCoord + 2, zCoord + 1, Block.stoneBrick.blockID, rand.nextInt(3), 2);
        world.setBlock(xCoord + 5, yCoord + 2, zCoord + 5, Block.stoneBrick.blockID, rand.nextInt(3), 2);
        world.setBlock(xCoord + 5, yCoord + 2, zCoord + 4, Block.stoneBrick.blockID, rand.nextInt(3), 2);
        world.setBlock(xCoord + 5, yCoord + 2, zCoord + 2, Block.stoneBrick.blockID, rand.nextInt(3), 2);
        world.setBlock(xCoord + 5, yCoord + 2, zCoord + 1, Block.stoneBrick.blockID, rand.nextInt(3), 2);
        world.setBlock(xCoord + 1, yCoord + 3, zCoord + 5, Block.stoneBrick.blockID, rand.nextInt(3), 2);
        world.setBlock(xCoord + 1, yCoord + 3, zCoord + 4, Block.stoneBrick.blockID, rand.nextInt(3), 2);
        world.setBlock(xCoord + 1, yCoord + 3, zCoord + 3, Block.stoneBrick.blockID, rand.nextInt(3), 2);
        world.setBlock(xCoord + 1, yCoord + 3, zCoord + 2, Block.stoneBrick.blockID, rand.nextInt(3), 2);
        world.setBlock(xCoord + 1, yCoord + 3, zCoord + 1, Block.stoneBrick.blockID, rand.nextInt(3), 2);
        world.setBlock(xCoord + 2, yCoord + 3, zCoord + 5, Block.stoneBrick.blockID, rand.nextInt(3), 2);
        world.setBlockToAir(xCoord + 2, yCoord + 3, zCoord + 4);
        world.setBlockToAir(xCoord + 2, yCoord + 3, zCoord + 3);
        world.setBlock(xCoord + 2, yCoord + 3, zCoord + 2, Block.stoneSingleSlab.blockID, 5, 2);
        world.setBlock(xCoord + 2, yCoord + 3, zCoord + 1, Block.stoneBrick.blockID, rand.nextInt(3), 2);
        world.setBlock(xCoord + 3, yCoord + 3, zCoord + 5, Block.stoneBrick.blockID, rand.nextInt(3), 2);
        world.setBlockToAir(xCoord + 3, yCoord + 3, zCoord + 4);
        world.setBlockToAir(xCoord + 3, yCoord + 3, zCoord + 3);
        world.setBlock(xCoord + 3, yCoord + 3, zCoord + 2, Block.stoneBrick.blockID, rand.nextInt(3), 2);
        world.setBlock(xCoord + 3, yCoord + 3, zCoord + 1, Block.stoneBrick.blockID, rand.nextInt(3), 2);
        world.setBlock(xCoord + 4, yCoord + 3, zCoord + 5, Block.stoneBrick.blockID, rand.nextInt(3), 2);
        world.setBlockToAir(xCoord + 4, yCoord + 3, zCoord + 4);
        world.setBlockToAir(xCoord + 4, yCoord + 3, zCoord + 3);
        world.setBlock(xCoord + 4, yCoord + 3, zCoord + 2, Block.stoneBrick.blockID, rand.nextInt(3), 2);
        world.setBlock(xCoord + 4, yCoord + 3, zCoord + 1, Block.stoneBrick.blockID, rand.nextInt(3), 2);
        world.setBlock(xCoord + 5, yCoord + 3, zCoord + 5, Block.stoneBrick.blockID, rand.nextInt(3), 2);
        world.setBlock(xCoord + 5, yCoord + 3, zCoord + 4, Block.stoneBrick.blockID, rand.nextInt(3), 2);
        world.setBlock(xCoord + 5, yCoord + 3, zCoord + 3, Block.stoneBrick.blockID, rand.nextInt(3), 2);
        world.setBlock(xCoord + 5, yCoord + 3, zCoord + 2, Block.stoneBrick.blockID, rand.nextInt(3), 2);
        world.setBlock(xCoord + 5, yCoord + 3, zCoord + 1, Block.stoneBrick.blockID, rand.nextInt(3), 2);
        world.setBlock(xCoord + 0, yCoord + 4, zCoord + 3, Block.torchWood.blockID);
        world.setBlock(xCoord + 1, yCoord + 4, zCoord + 5, Block.stoneBrick.blockID, rand.nextInt(3), 2);
        world.setBlock(xCoord + 1, yCoord + 4, zCoord + 4, Block.stoneBrick.blockID, rand.nextInt(3), 2);
        world.setBlock(xCoord + 1, yCoord + 4, zCoord + 3, Block.stoneBrick.blockID, rand.nextInt(3), 2);
        world.setBlock(xCoord + 1, yCoord + 4, zCoord + 2, Block.stoneBrick.blockID, rand.nextInt(3), 2);
        world.setBlock(xCoord + 1, yCoord + 4, zCoord + 1, Block.stoneBrick.blockID, rand.nextInt(3), 2);
        world.setBlock(xCoord + 2, yCoord + 4, zCoord + 5, Block.stoneBrick.blockID, rand.nextInt(3), 2);
        world.setBlockToAir(xCoord + 2, yCoord + 4, zCoord + 4);
        world.setBlock(xCoord + 2, yCoord + 4, zCoord + 3, Block.torchWood.blockID);
        world.setBlockToAir(xCoord + 2, yCoord + 4, zCoord + 2);
        world.setBlock(xCoord + 2, yCoord + 4, zCoord + 1, Block.stoneBrick.blockID, rand.nextInt(3), 2);
        world.setBlock(xCoord + 3, yCoord + 4, zCoord + 6, Block.torchWood.blockID);
        world.setBlock(xCoord + 3, yCoord + 4, zCoord + 5, Block.stoneBrick.blockID, rand.nextInt(3), 2);
        world.setBlockToAir(xCoord + 3, yCoord + 4, zCoord + 4);
        world.setBlockToAir(xCoord + 3, yCoord + 4, zCoord + 3);
        world.setBlockToAir(xCoord + 3, yCoord + 4, zCoord + 2);
        world.setBlock(xCoord + 3, yCoord + 4, zCoord + 1, Block.stoneBrick.blockID, rand.nextInt(3), 2);
        world.setBlock(xCoord + 3, yCoord + 4, zCoord + 0, Block.torchWood.blockID);
        world.setBlock(xCoord + 4, yCoord + 4, zCoord + 5, Block.stoneBrick.blockID, rand.nextInt(3), 2);
        world.setBlockToAir(xCoord + 4, yCoord + 4, zCoord + 4);
        world.setBlock(xCoord + 4, yCoord + 4, zCoord + 3, Block.stoneBrick.blockID, rand.nextInt(3), 2);
        world.setBlock(xCoord + 4, yCoord + 4, zCoord + 2, Block.stoneSingleSlab.blockID, 5, 2);
        world.setBlock(xCoord + 4, yCoord + 4, zCoord + 1, Block.stoneBrick.blockID, rand.nextInt(3), 2);
        world.setBlock(xCoord + 5, yCoord + 4, zCoord + 5, Block.stoneBrick.blockID, rand.nextInt(3), 2);
        world.setBlock(xCoord + 5, yCoord + 4, zCoord + 4, Block.stoneBrick.blockID, rand.nextInt(3), 2);
        world.setBlock(xCoord + 5, yCoord + 4, zCoord + 3, Block.stoneBrick.blockID, rand.nextInt(3), 2);
        world.setBlock(xCoord + 5, yCoord + 4, zCoord + 2, Block.stoneBrick.blockID, rand.nextInt(3), 2);
        world.setBlock(xCoord + 5, yCoord + 4, zCoord + 1, Block.stoneBrick.blockID, rand.nextInt(3), 2);
        world.setBlock(xCoord + 6, yCoord + 4, zCoord + 3, Block.torchWood.blockID);
        world.setBlock(xCoord + 1, yCoord + 5, zCoord + 5, Block.stoneBrick.blockID, rand.nextInt(3), 2);
        world.setBlock(xCoord + 1, yCoord + 5, zCoord + 4, Block.stoneBrick.blockID, rand.nextInt(3), 2);
        world.setBlock(xCoord + 1, yCoord + 5, zCoord + 3, Block.stoneBrick.blockID, rand.nextInt(3), 2);
        world.setBlock(xCoord + 1, yCoord + 5, zCoord + 2, Block.stoneBrick.blockID, rand.nextInt(3), 2);
        world.setBlock(xCoord + 1, yCoord + 5, zCoord + 1, Block.stoneBrick.blockID, rand.nextInt(3), 2);
        world.setBlock(xCoord + 2, yCoord + 5, zCoord + 5, Block.stoneBrick.blockID, rand.nextInt(3), 2);
        world.setBlockToAir(xCoord + 2, yCoord + 5, zCoord + 4);
        world.setBlockToAir(xCoord + 2, yCoord + 5, zCoord + 3);
        world.setBlockToAir(xCoord + 2, yCoord + 5, zCoord + 2);
        world.setBlock(xCoord + 2, yCoord + 5, zCoord + 1, Block.stoneBrick.blockID, rand.nextInt(3), 2);
        world.setBlock(xCoord + 3, yCoord + 5, zCoord + 5, Block.stoneBrick.blockID, rand.nextInt(3), 2);
        world.setBlock(xCoord + 3, yCoord + 5, zCoord + 4, Block.stoneBrick.blockID, rand.nextInt(3), 2);
        world.setBlockToAir(xCoord + 3, yCoord + 5, zCoord + 3);
        world.setBlockToAir(xCoord + 3, yCoord + 5, zCoord + 2);
        world.setBlock(xCoord + 3, yCoord + 5, zCoord + 1, Block.stoneBrick.blockID, rand.nextInt(3), 2);
        world.setBlock(xCoord + 4, yCoord + 5, zCoord + 5, Block.stoneBrick.blockID, rand.nextInt(3), 2);
        world.setBlock(xCoord + 4, yCoord + 5, zCoord + 4, Block.stoneSingleSlab.blockID, 5, 2);
        world.setBlockToAir(xCoord + 4, yCoord + 5, zCoord + 3);
        world.setBlockToAir(xCoord + 4, yCoord + 5, zCoord + 2);
        world.setBlock(xCoord + 4, yCoord + 5, zCoord + 1, Block.stoneBrick.blockID, rand.nextInt(3), 2);
        world.setBlock(xCoord + 5, yCoord + 5, zCoord + 5, Block.stoneBrick.blockID, rand.nextInt(3), 2);
        world.setBlock(xCoord + 5, yCoord + 5, zCoord + 4, Block.stoneBrick.blockID, rand.nextInt(3), 2);
        world.setBlock(xCoord + 5, yCoord + 5, zCoord + 3, Block.stoneBrick.blockID, rand.nextInt(3), 2);
        world.setBlock(xCoord + 5, yCoord + 5, zCoord + 2, Block.stoneBrick.blockID, rand.nextInt(3), 2);
        world.setBlock(xCoord + 5, yCoord + 5, zCoord + 1, Block.stoneBrick.blockID, rand.nextInt(3), 2);
        world.setBlock(xCoord + 1, yCoord + 6, zCoord + 5, Block.stoneBrick.blockID, rand.nextInt(3), 2);
        world.setBlock(xCoord + 1, yCoord + 6, zCoord + 4, Block.stoneBrick.blockID, rand.nextInt(3), 2);
        world.setBlock(xCoord + 1, yCoord + 6, zCoord + 3, Block.stoneBrick.blockID, rand.nextInt(3), 2);
        world.setBlock(xCoord + 1, yCoord + 6, zCoord + 2, Block.stoneBrick.blockID, rand.nextInt(3), 2);
        world.setBlock(xCoord + 1, yCoord + 6, zCoord + 1, Block.stoneBrick.blockID, rand.nextInt(3), 2);
        world.setBlock(xCoord + 2, yCoord + 6, zCoord + 5, Block.stoneBrick.blockID, rand.nextInt(3), 2);
        world.setBlock(xCoord + 2, yCoord + 6, zCoord + 4, Block.stoneSingleSlab.blockID, 5, 2);
        world.setBlock(xCoord + 2, yCoord + 6, zCoord + 3, Block.stoneBrick.blockID, rand.nextInt(3), 2);
        world.setBlockToAir(xCoord + 2, yCoord + 6, zCoord + 2);
        world.setBlock(xCoord + 2, yCoord + 6, zCoord + 1, Block.stoneBrick.blockID, rand.nextInt(3), 2);
        world.setBlock(xCoord + 3, yCoord + 6, zCoord + 5, Block.stoneBrick.blockID, rand.nextInt(3), 2);
        world.setBlockToAir(xCoord + 3, yCoord + 6, zCoord + 4);
        world.setBlockToAir(xCoord + 3, yCoord + 6, zCoord + 3);
        world.setBlockToAir(xCoord + 3, yCoord + 6, zCoord + 2);
        world.setBlock(xCoord + 3, yCoord + 6, zCoord + 1, Block.stoneBrick.blockID, rand.nextInt(3), 2);
        world.setBlock(xCoord + 4, yCoord + 6, zCoord + 5, Block.stoneBrick.blockID, rand.nextInt(3), 2);
        world.setBlockToAir(xCoord + 4, yCoord + 6, zCoord + 4);
        world.setBlock(xCoord + 4, yCoord + 6, zCoord + 3, Block.torchWood.blockID);
        world.setBlockToAir(xCoord + 4, yCoord + 6, zCoord + 2);
        world.setBlock(xCoord + 4, yCoord + 6, zCoord + 1, Block.stoneBrick.blockID, rand.nextInt(3), 2);
        world.setBlock(xCoord + 5, yCoord + 6, zCoord + 5, Block.stoneBrick.blockID, rand.nextInt(3), 2);
        world.setBlock(xCoord + 5, yCoord + 6, zCoord + 4, Block.stoneBrick.blockID, rand.nextInt(3), 2);
        world.setBlock(xCoord + 5, yCoord + 6, zCoord + 3, Block.stoneBrick.blockID, rand.nextInt(3), 2);
        world.setBlock(xCoord + 5, yCoord + 6, zCoord + 2, Block.stoneBrick.blockID, rand.nextInt(3), 2);
        world.setBlock(xCoord + 5, yCoord + 6, zCoord + 1, Block.stoneBrick.blockID, rand.nextInt(3), 2);
        world.setBlock(xCoord + 1, yCoord + 7, zCoord + 5, Block.stoneBrick.blockID, rand.nextInt(3), 2);
        world.setBlock(xCoord + 1, yCoord + 7, zCoord + 4, Block.stoneBrick.blockID, rand.nextInt(3), 2);
        world.setBlock(xCoord + 1, yCoord + 7, zCoord + 3, Block.stoneBrick.blockID, rand.nextInt(3), 2);
        world.setBlock(xCoord + 1, yCoord + 7, zCoord + 2, Block.stoneBrick.blockID, rand.nextInt(3), 2);
        world.setBlock(xCoord + 1, yCoord + 7, zCoord + 1, Block.stoneBrick.blockID, rand.nextInt(3), 2);
        world.setBlock(xCoord + 2, yCoord + 7, zCoord + 5, Block.stoneBrick.blockID, rand.nextInt(3), 2);
        world.setBlockToAir(xCoord + 2, yCoord + 7, zCoord + 4);
        world.setBlockToAir(xCoord + 2, yCoord + 7, zCoord + 3);
        world.setBlock(xCoord + 2, yCoord + 7, zCoord + 2, Block.stoneSingleSlab.blockID, 5, 2);
        world.setBlock(xCoord + 2, yCoord + 7, zCoord + 1, Block.stoneBrick.blockID, rand.nextInt(3), 2);
        world.setBlock(xCoord + 3, yCoord + 7, zCoord + 5, Block.stoneBrick.blockID, rand.nextInt(3), 2);
        world.setBlockToAir(xCoord + 3, yCoord + 7, zCoord + 4);
        world.setBlockToAir(xCoord + 3, yCoord + 7, zCoord + 3);
        world.setBlock(xCoord + 3, yCoord + 7, zCoord + 2, Block.stoneBrick.blockID, rand.nextInt(3), 2);
        world.setBlock(xCoord + 3, yCoord + 7, zCoord + 1, Block.stoneBrick.blockID, rand.nextInt(3), 2);
        world.setBlock(xCoord + 4, yCoord + 7, zCoord + 5, Block.stoneBrick.blockID, rand.nextInt(3), 2);
        world.setBlockToAir(xCoord + 4, yCoord + 7, zCoord + 4);
        world.setBlockToAir(xCoord + 4, yCoord + 7, zCoord + 3);
        world.setBlockToAir(xCoord + 4, yCoord + 7, zCoord + 2);
        world.setBlock(xCoord + 4, yCoord + 7, zCoord + 1, Block.stoneBrick.blockID, rand.nextInt(3), 2);
        world.setBlock(xCoord + 5, yCoord + 7, zCoord + 5, Block.stoneBrick.blockID, rand.nextInt(3), 2);
        world.setBlock(xCoord + 5, yCoord + 7, zCoord + 4, Block.stoneBrick.blockID, rand.nextInt(3), 2);
        world.setBlock(xCoord + 5, yCoord + 7, zCoord + 3, Block.stoneBrick.blockID, rand.nextInt(3), 2);
        world.setBlock(xCoord + 5, yCoord + 7, zCoord + 2, Block.stoneBrick.blockID, rand.nextInt(3), 2);
        world.setBlock(xCoord + 5, yCoord + 7, zCoord + 1, Block.stoneBrick.blockID, rand.nextInt(3), 2);
        world.setBlock(xCoord + 1, yCoord + 8, zCoord + 5, Block.stoneBrick.blockID, rand.nextInt(3), 2);
        world.setBlock(xCoord + 1, yCoord + 8, zCoord + 4, Block.stoneBrick.blockID, rand.nextInt(3), 2);
        world.setBlock(xCoord + 1, yCoord + 8, zCoord + 3, Block.stoneBrick.blockID, rand.nextInt(3), 2);
        world.setBlock(xCoord + 1, yCoord + 8, zCoord + 2, Block.stoneBrick.blockID, rand.nextInt(3), 2);
        world.setBlock(xCoord + 1, yCoord + 8, zCoord + 1, Block.stoneBrick.blockID, rand.nextInt(3), 2);
        world.setBlock(xCoord + 2, yCoord + 8, zCoord + 5, Block.stoneBrick.blockID, rand.nextInt(3), 2);
        world.setBlockToAir(xCoord + 2, yCoord + 8, zCoord + 4);
        world.setBlock(xCoord + 2, yCoord + 8, zCoord + 3, Block.torchWood.blockID);
        world.setBlockToAir(xCoord + 2, yCoord + 8, zCoord + 2);
        world.setBlock(xCoord + 2, yCoord + 8, zCoord + 1, Block.stoneBrick.blockID, rand.nextInt(3), 2);
        world.setBlock(xCoord + 3, yCoord + 8, zCoord + 5, Block.stoneBrick.blockID, rand.nextInt(3), 2);
        world.setBlockToAir(xCoord + 3, yCoord + 8, zCoord + 4);
        world.setBlockToAir(xCoord + 3, yCoord + 8, zCoord + 3);
        world.setBlockToAir(xCoord + 3, yCoord + 8, zCoord + 2);
        world.setBlock(xCoord + 3, yCoord + 8, zCoord + 1, Block.stoneBrick.blockID, rand.nextInt(3), 2);
        world.setBlock(xCoord + 4, yCoord + 8, zCoord + 5, Block.stoneBrick.blockID, rand.nextInt(3), 2);
        world.setBlockToAir(xCoord + 4, yCoord + 8, zCoord + 4);
        world.setBlock(xCoord + 4, yCoord + 8, zCoord + 3, Block.stoneBrick.blockID, rand.nextInt(3), 2);
        world.setBlock(xCoord + 4, yCoord + 8, zCoord + 2, Block.stoneSingleSlab.blockID, 5, 2);
        world.setBlock(xCoord + 4, yCoord + 8, zCoord + 1, Block.stoneBrick.blockID, rand.nextInt(3), 2);
        world.setBlock(xCoord + 5, yCoord + 8, zCoord + 5, Block.stoneBrick.blockID, rand.nextInt(3), 2);
        world.setBlock(xCoord + 5, yCoord + 8, zCoord + 4, Block.stoneBrick.blockID, rand.nextInt(3), 2);
        world.setBlock(xCoord + 5, yCoord + 8, zCoord + 3, Block.stoneBrick.blockID, rand.nextInt(3), 2);
        world.setBlock(xCoord + 5, yCoord + 8, zCoord + 2, Block.stoneBrick.blockID, rand.nextInt(3), 2);
        world.setBlock(xCoord + 5, yCoord + 8, zCoord + 1, Block.stoneBrick.blockID, rand.nextInt(3), 2);
        world.setBlock(xCoord + 1, yCoord + 9, zCoord + 5, Block.stoneBrick.blockID, rand.nextInt(3), 2);
        world.setBlock(xCoord + 1, yCoord + 9, zCoord + 4, Block.stoneBrick.blockID, rand.nextInt(3), 2);
        world.setBlock(xCoord + 1, yCoord + 9, zCoord + 3, Block.stoneBrick.blockID, rand.nextInt(3), 2);
        world.setBlock(xCoord + 1, yCoord + 9, zCoord + 2, Block.stoneBrick.blockID, rand.nextInt(3), 2);
        world.setBlock(xCoord + 1, yCoord + 9, zCoord + 1, Block.stoneBrick.blockID, rand.nextInt(3), 2);
        world.setBlock(xCoord + 2, yCoord + 9, zCoord + 5, Block.stoneBrick.blockID, rand.nextInt(3), 2);
        world.setBlockToAir(xCoord + 2, yCoord + 9, zCoord + 4);
        world.setBlockToAir(xCoord + 2, yCoord + 9, zCoord + 3);
        world.setBlockToAir(xCoord + 2, yCoord + 9, zCoord + 2);
        world.setBlock(xCoord + 2, yCoord + 9, zCoord + 1, Block.stoneBrick.blockID, rand.nextInt(3), 2);
        world.setBlock(xCoord + 3, yCoord + 9, zCoord + 5, Block.stoneBrick.blockID, rand.nextInt(3), 2);
        world.setBlock(xCoord + 3, yCoord + 9, zCoord + 4, Block.stoneBrick.blockID, rand.nextInt(3), 2);
        world.setBlockToAir(xCoord + 3, yCoord + 9, zCoord + 3);
        world.setBlockToAir(xCoord + 3, yCoord + 9, zCoord + 2);
        world.setBlock(xCoord + 3, yCoord + 9, zCoord + 1, Block.stoneBrick.blockID, rand.nextInt(3), 2);
        world.setBlock(xCoord + 4, yCoord + 9, zCoord + 5, Block.stoneBrick.blockID, rand.nextInt(3), 2);
        world.setBlock(xCoord + 4, yCoord + 9, zCoord + 4, Block.stoneSingleSlab.blockID, 5, 2);
        world.setBlockToAir(xCoord + 4, yCoord + 9, zCoord + 3);
        world.setBlockToAir(xCoord + 4, yCoord + 9, zCoord + 2);
        world.setBlock(xCoord + 4, yCoord + 9, zCoord + 1, Block.stoneBrick.blockID, rand.nextInt(3), 2);
        world.setBlock(xCoord + 5, yCoord + 9, zCoord + 5, Block.stoneBrick.blockID, rand.nextInt(3), 2);
        world.setBlock(xCoord + 5, yCoord + 9, zCoord + 4, Block.stoneBrick.blockID, rand.nextInt(3), 2);
        world.setBlock(xCoord + 5, yCoord + 9, zCoord + 3, Block.stoneBrick.blockID, rand.nextInt(3), 2);
        world.setBlock(xCoord + 5, yCoord + 9, zCoord + 2, Block.stoneBrick.blockID, rand.nextInt(3), 2);
        world.setBlock(xCoord + 5, yCoord + 9, zCoord + 1, Block.stoneBrick.blockID, rand.nextInt(3), 2);
        world.setBlock(xCoord + 0, yCoord + 10, zCoord + 6, Block.stoneBrick.blockID, rand.nextInt(3), 2);
        world.setBlock(xCoord + 0, yCoord + 10, zCoord + 5, Block.stoneBrick.blockID, rand.nextInt(3), 2);
        world.setBlock(xCoord + 0, yCoord + 10, zCoord + 4, Block.stoneBrick.blockID, rand.nextInt(3), 2);
        world.setBlock(xCoord + 0, yCoord + 10, zCoord + 3, Block.stoneBrick.blockID, rand.nextInt(3), 2);
        world.setBlock(xCoord + 0, yCoord + 10, zCoord + 2, Block.stoneBrick.blockID, rand.nextInt(3), 2);
        world.setBlock(xCoord + 0, yCoord + 10, zCoord + 1, Block.stoneBrick.blockID, rand.nextInt(3), 2);
        world.setBlock(xCoord + 0, yCoord + 10, zCoord + 0, Block.stoneBrick.blockID, rand.nextInt(3), 2);
        world.setBlock(xCoord + 1, yCoord + 10, zCoord + 6, Block.stoneBrick.blockID, rand.nextInt(3), 2);
        world.setBlock(xCoord + 1, yCoord + 10, zCoord + 5, Block.stoneBrick.blockID, rand.nextInt(3), 2);
        world.setBlock(xCoord + 1, yCoord + 10, zCoord + 4, Block.stoneBrick.blockID, rand.nextInt(3), 2);
        world.setBlock(xCoord + 1, yCoord + 10, zCoord + 3, Block.stoneBrick.blockID, rand.nextInt(3), 2);
        world.setBlock(xCoord + 1, yCoord + 10, zCoord + 2, Block.stoneBrick.blockID, rand.nextInt(3), 2);
        world.setBlock(xCoord + 1, yCoord + 10, zCoord + 1, Block.stoneBrick.blockID, rand.nextInt(3), 2);
        world.setBlock(xCoord + 1, yCoord + 10, zCoord + 0, Block.stoneBrick.blockID, rand.nextInt(3), 2);
        world.setBlock(xCoord + 2, yCoord + 10, zCoord + 6, Block.stoneBrick.blockID, rand.nextInt(3), 2);
        world.setBlock(xCoord + 2, yCoord + 10, zCoord + 5, Block.stoneBrick.blockID, rand.nextInt(3), 2);
        world.setBlock(xCoord + 2, yCoord + 10, zCoord + 4, Block.stoneSingleSlab.blockID, 5, 2);
        world.setBlock(xCoord + 2, yCoord + 10, zCoord + 3, Block.stoneBrick.blockID, rand.nextInt(3), 2);
        world.setBlock(xCoord + 2, yCoord + 10, zCoord + 2, Block.stoneBrick.blockID, rand.nextInt(3), 2);
        world.setBlock(xCoord + 2, yCoord + 10, zCoord + 1, Block.stoneBrick.blockID, rand.nextInt(3), 2);
        world.setBlock(xCoord + 2, yCoord + 10, zCoord + 0, Block.stoneBrick.blockID, rand.nextInt(3), 2);
        world.setBlock(xCoord + 3, yCoord + 10, zCoord + 6, Block.stoneBrick.blockID, rand.nextInt(3), 2);
        world.setBlock(xCoord + 3, yCoord + 10, zCoord + 5, Block.stoneBrick.blockID, rand.nextInt(3), 2);
        world.setBlockToAir(xCoord + 3, yCoord + 10, zCoord + 4);
        world.setBlockToAir(xCoord + 3, yCoord + 10, zCoord + 3);
        world.setBlockToAir(xCoord + 3, yCoord + 10, zCoord + 2);
        world.setBlock(xCoord + 3, yCoord + 10, zCoord + 1, Block.stoneBrick.blockID, rand.nextInt(3), 2);
        world.setBlock(xCoord + 3, yCoord + 10, zCoord + 0, Block.stoneBrick.blockID, rand.nextInt(3), 2);
        world.setBlock(xCoord + 4, yCoord + 10, zCoord + 6, Block.stoneBrick.blockID, rand.nextInt(3), 2);
        world.setBlock(xCoord + 4, yCoord + 10, zCoord + 5, Block.stoneBrick.blockID, rand.nextInt(3), 2);
        world.setBlockToAir(xCoord + 4, yCoord + 10, zCoord + 4);
        world.setBlockToAir(xCoord + 4, yCoord + 10, zCoord + 3);
        world.setBlockToAir(xCoord + 4, yCoord + 10, zCoord + 2);
        world.setBlock(xCoord + 4, yCoord + 10, zCoord + 1, Block.stoneBrick.blockID, rand.nextInt(3), 2);
        world.setBlock(xCoord + 4, yCoord + 10, zCoord + 0, Block.stoneBrick.blockID, rand.nextInt(3), 2);
        world.setBlock(xCoord + 5, yCoord + 10, zCoord + 6, Block.stoneBrick.blockID, rand.nextInt(3), 2);
        world.setBlock(xCoord + 5, yCoord + 10, zCoord + 5, Block.stoneBrick.blockID, rand.nextInt(3), 2);
        world.setBlock(xCoord + 5, yCoord + 10, zCoord + 4, Block.stoneBrick.blockID, rand.nextInt(3), 2);
        world.setBlock(xCoord + 5, yCoord + 10, zCoord + 3, Block.stoneBrick.blockID, rand.nextInt(3), 2);
        world.setBlock(xCoord + 5, yCoord + 10, zCoord + 2, Block.stoneBrick.blockID, rand.nextInt(3), 2);
        world.setBlock(xCoord + 5, yCoord + 10, zCoord + 1, Block.stoneBrick.blockID, rand.nextInt(3), 2);
        world.setBlock(xCoord + 5, yCoord + 10, zCoord + 0, Block.stoneBrick.blockID, rand.nextInt(3), 2);
        world.setBlock(xCoord + 6, yCoord + 10, zCoord + 6, Block.stoneBrick.blockID, rand.nextInt(3), 2);
        world.setBlock(xCoord + 6, yCoord + 10, zCoord + 5, Block.stoneBrick.blockID, rand.nextInt(3), 2);
        world.setBlock(xCoord + 6, yCoord + 10, zCoord + 4, Block.stoneBrick.blockID, rand.nextInt(3), 2);
        world.setBlock(xCoord + 6, yCoord + 10, zCoord + 3, Block.stoneBrick.blockID, rand.nextInt(3), 2);
        world.setBlock(xCoord + 6, yCoord + 10, zCoord + 2, Block.stoneBrick.blockID, rand.nextInt(3), 2);
        world.setBlock(xCoord + 6, yCoord + 10, zCoord + 1, Block.stoneBrick.blockID, rand.nextInt(3), 2);
        world.setBlock(xCoord + 6, yCoord + 10, zCoord + 0, Block.stoneBrick.blockID, rand.nextInt(3), 2);
        world.setBlock(xCoord + 0, yCoord + 11, zCoord + 6, Block.stoneBrick.blockID, rand.nextInt(3), 2);
        world.setBlock(xCoord + 0, yCoord + 11, zCoord + 4, Block.stoneBrick.blockID, rand.nextInt(3), 2);
        world.setBlock(xCoord + 0, yCoord + 11, zCoord + 2, Block.stoneBrick.blockID, rand.nextInt(3), 2);
        world.setBlock(xCoord + 0, yCoord + 11, zCoord + 0, Block.stoneBrick.blockID, rand.nextInt(3), 2);
        world.setBlockToAir(xCoord + 1, yCoord + 11, zCoord + 5);
        world.setBlockToAir(xCoord + 1, yCoord + 11, zCoord + 4);
        world.setBlockToAir(xCoord + 1, yCoord + 11, zCoord + 3);
        world.setBlockToAir(xCoord + 1, yCoord + 11, zCoord + 2);
        world.setBlockToAir(xCoord + 1, yCoord + 11, zCoord + 1);
        world.setBlock(xCoord + 2, yCoord + 11, zCoord + 6, Block.stoneBrick.blockID, rand.nextInt(3), 2);
        world.setBlockToAir(xCoord + 2, yCoord + 11, zCoord + 5);
        world.setBlockToAir(xCoord + 2, yCoord + 11, zCoord + 4);
        world.setBlockToAir(xCoord + 2, yCoord + 11, zCoord + 3);
        world.setBlockToAir(xCoord + 2, yCoord + 11, zCoord + 2);
        world.setBlockToAir(xCoord + 2, yCoord + 11, zCoord + 1);
        world.setBlock(xCoord + 2, yCoord + 11, zCoord + 0, Block.stoneBrick.blockID, rand.nextInt(3), 2);
        world.setBlockToAir(xCoord + 3, yCoord + 11, zCoord + 5);
        world.setBlockToAir(xCoord + 3, yCoord + 11, zCoord + 4);
        world.setBlockToAir(xCoord + 3, yCoord + 11, zCoord + 3);
        world.setBlockToAir(xCoord + 3, yCoord + 11, zCoord + 2);
        world.setBlockToAir(xCoord + 3, yCoord + 11, zCoord + 1);
        world.setBlock(xCoord + 4, yCoord + 11, zCoord + 6, Block.stoneBrick.blockID, rand.nextInt(3), 2);
        world.setBlockToAir(xCoord + 4, yCoord + 11, zCoord + 5);
        world.setBlockToAir(xCoord + 4, yCoord + 11, zCoord + 4);
        world.setBlockToAir(xCoord + 4, yCoord + 11, zCoord + 3);
        world.setBlockToAir(xCoord + 4, yCoord + 11, zCoord + 2);
        world.setBlockToAir(xCoord + 4, yCoord + 11, zCoord + 1);
        world.setBlock(xCoord + 4, yCoord + 11, zCoord + 0, Block.stoneBrick.blockID, rand.nextInt(3), 2);

        int chest = Blocks.chestLoot.blockID;
        world.setBlock(xCoord + 5, yCoord + 11, zCoord + 5, chest);
        TileEntity tileentitychest = world.getBlockTileEntity(xCoord + 5, yCoord + 11, zCoord + 5);
        if (tileentitychest != null)
        {
            WeightedRandomChestContent.generateChestContents(rand, LootManager.loot, (TileEntityChest) tileentitychest, rand.nextInt(5) + 1);
        }
        ChatHandler.logDebug("Day Z Fort Chest Created At " + (xCoord + 5) + ", " + (yCoord + 11) + ", " + (zCoord + 5) + ".");

        world.setBlockToAir(xCoord + 5, yCoord + 11, zCoord + 4);
        world.setBlockToAir(xCoord + 5, yCoord + 11, zCoord + 3);
        world.setBlockToAir(xCoord + 5, yCoord + 11, zCoord + 2);
        world.setBlockToAir(xCoord + 5, yCoord + 11, zCoord + 1);
        world.setBlock(xCoord + 6, yCoord + 11, zCoord + 6, Block.stoneBrick.blockID, rand.nextInt(3), 2);
        world.setBlock(xCoord + 6, yCoord + 11, zCoord + 4, Block.stoneBrick.blockID, rand.nextInt(3), 2);
        world.setBlock(xCoord + 6, yCoord + 11, zCoord + 2, Block.stoneBrick.blockID, rand.nextInt(3), 2);
        world.setBlock(xCoord + 6, yCoord + 11, zCoord + 0, Block.stoneBrick.blockID, rand.nextInt(3), 2);
        world.setBlock(xCoord + 0, yCoord + 12, zCoord + 6, Block.torchWood.blockID);
        world.setBlock(xCoord + 0, yCoord + 12, zCoord + 4, Block.torchWood.blockID);
        world.setBlock(xCoord + 0, yCoord + 12, zCoord + 2, Block.torchWood.blockID);
        world.setBlock(xCoord + 0, yCoord + 12, zCoord + 0, Block.torchWood.blockID);
        world.setBlock(xCoord + 2, yCoord + 12, zCoord + 6, Block.torchWood.blockID);
        world.setBlock(xCoord + 2, yCoord + 12, zCoord + 0, Block.torchWood.blockID);
        world.setBlock(xCoord + 4, yCoord + 12, zCoord + 6, Block.torchWood.blockID);
        world.setBlock(xCoord + 4, yCoord + 12, zCoord + 0, Block.torchWood.blockID);
        world.setBlock(xCoord + 6, yCoord + 12, zCoord + 6, Block.torchWood.blockID);
        world.setBlock(xCoord + 6, yCoord + 12, zCoord + 4, Block.torchWood.blockID);
        world.setBlock(xCoord + 6, yCoord + 12, zCoord + 2, Block.torchWood.blockID);
        world.setBlock(xCoord + 6, yCoord + 12, zCoord + 0, Block.torchWood.blockID);
        return true;
    }
}