package dayz.common.world.generation.structures;

import java.util.Random;

import net.minecraft.block.Block;
import net.minecraft.item.ItemDoor;
import net.minecraft.tileentity.TileEntity;
import net.minecraft.tileentity.TileEntityChest;
import net.minecraft.util.WeightedRandomChestContent;
import net.minecraft.world.World;
import dayz.common.blocks.Blocks;
import dayz.common.misc.ChatHandler;
import dayz.common.misc.LootManager;

public class StructureHouse implements IStructure
{
    @Override
    public boolean generate(World world, Random rand, int xCoord, int yCoord, int zCoord)
    {
        int bID = 2;

        if (world.getBlockId(xCoord, yCoord, zCoord) != bID || world.getBlockId(xCoord, yCoord + 1, zCoord) != 0 || world.getBlockId(xCoord + 7, yCoord, zCoord) != bID || world.getBlockId(xCoord + 7, yCoord, zCoord + 7) != bID || world.getBlockId(xCoord, yCoord, zCoord + 7) != bID || world.getBlockId(xCoord + 7, yCoord + 1, zCoord) != 0 || world.getBlockId(xCoord + 7, yCoord + 1, zCoord + 7) != 0 || world.getBlockId(xCoord, yCoord + 1, zCoord + 7) != 0)
        {
            return false;
        }

        world.setBlock(xCoord + 1, yCoord + 0, zCoord + 9, Block.cobblestone.blockID);
        world.setBlock(xCoord + 1, yCoord + 0, zCoord + 8, Block.cobblestone.blockID);
        world.setBlock(xCoord + 1, yCoord + 0, zCoord + 7, Block.cobblestone.blockID);
        world.setBlock(xCoord + 1, yCoord + 0, zCoord + 6, Block.cobblestone.blockID);
        world.setBlock(xCoord + 1, yCoord + 0, zCoord + 5, Block.cobblestone.blockID);
        world.setBlock(xCoord + 1, yCoord + 0, zCoord + 4, Block.cobblestone.blockID);
        world.setBlock(xCoord + 1, yCoord + 0, zCoord + 3, Block.cobblestone.blockID);
        world.setBlock(xCoord + 1, yCoord + 0, zCoord + 2, Block.cobblestone.blockID);
        world.setBlock(xCoord + 1, yCoord + 0, zCoord + 1, Block.cobblestone.blockID);
        world.setBlock(xCoord + 2, yCoord + 0, zCoord + 9, Block.cobblestone.blockID);
        world.setBlock(xCoord + 2, yCoord + 0, zCoord + 8, Block.planks.blockID);
        world.setBlock(xCoord + 2, yCoord + 0, zCoord + 7, Block.planks.blockID);
        world.setBlock(xCoord + 2, yCoord + 0, zCoord + 6, Block.planks.blockID);
        world.setBlock(xCoord + 2, yCoord + 0, zCoord + 5, Block.planks.blockID);
        world.setBlock(xCoord + 2, yCoord + 0, zCoord + 4, Block.planks.blockID);
        world.setBlock(xCoord + 2, yCoord + 0, zCoord + 3, Block.planks.blockID);
        world.setBlock(xCoord + 2, yCoord + 0, zCoord + 2, Block.planks.blockID);
        world.setBlock(xCoord + 2, yCoord + 0, zCoord + 1, Block.cobblestone.blockID);
        world.setBlock(xCoord + 3, yCoord + 0, zCoord + 9, Block.cobblestone.blockID);
        world.setBlock(xCoord + 3, yCoord + 0, zCoord + 8, Block.planks.blockID);
        world.setBlock(xCoord + 3, yCoord + 0, zCoord + 7, Block.planks.blockID);
        world.setBlock(xCoord + 3, yCoord + 0, zCoord + 6, Block.planks.blockID);
        world.setBlock(xCoord + 3, yCoord + 0, zCoord + 5, Block.planks.blockID);
        world.setBlock(xCoord + 3, yCoord + 0, zCoord + 4, Block.planks.blockID);
        world.setBlock(xCoord + 3, yCoord + 0, zCoord + 3, Block.planks.blockID);
        world.setBlock(xCoord + 3, yCoord + 0, zCoord + 2, Block.planks.blockID);
        world.setBlock(xCoord + 3, yCoord + 0, zCoord + 1, Block.cobblestone.blockID);
        world.setBlock(xCoord + 4, yCoord + 0, zCoord + 9, Block.cobblestone.blockID);
        world.setBlock(xCoord + 4, yCoord + 0, zCoord + 8, Block.planks.blockID);
        world.setBlock(xCoord + 4, yCoord + 0, zCoord + 7, Block.planks.blockID);
        world.setBlock(xCoord + 4, yCoord + 0, zCoord + 6, Block.planks.blockID);
        world.setBlock(xCoord + 4, yCoord + 0, zCoord + 5, Block.planks.blockID);
        world.setBlock(xCoord + 4, yCoord + 0, zCoord + 4, Block.planks.blockID);
        world.setBlock(xCoord + 4, yCoord + 0, zCoord + 3, Block.planks.blockID);
        world.setBlock(xCoord + 4, yCoord + 0, zCoord + 2, Block.planks.blockID);
        world.setBlock(xCoord + 4, yCoord + 0, zCoord + 1, Block.cobblestone.blockID);
        world.setBlock(xCoord + 5, yCoord + 0, zCoord + 9, Block.cobblestone.blockID);
        world.setBlock(xCoord + 5, yCoord + 0, zCoord + 8, Block.planks.blockID);
        world.setBlock(xCoord + 5, yCoord + 0, zCoord + 7, Block.planks.blockID);
        world.setBlock(xCoord + 5, yCoord + 0, zCoord + 6, Block.planks.blockID);
        world.setBlock(xCoord + 5, yCoord + 0, zCoord + 5, Block.planks.blockID);
        world.setBlock(xCoord + 5, yCoord + 0, zCoord + 4, Block.planks.blockID);
        world.setBlock(xCoord + 5, yCoord + 0, zCoord + 3, Block.planks.blockID);
        world.setBlock(xCoord + 5, yCoord + 0, zCoord + 2, Block.planks.blockID);
        world.setBlock(xCoord + 5, yCoord + 0, zCoord + 1, Block.cobblestone.blockID);
        world.setBlock(xCoord + 6, yCoord + 0, zCoord + 9, Block.cobblestone.blockID);
        world.setBlock(xCoord + 6, yCoord + 0, zCoord + 8, Block.planks.blockID);
        world.setBlock(xCoord + 6, yCoord + 0, zCoord + 7, Block.planks.blockID);
        world.setBlock(xCoord + 6, yCoord + 0, zCoord + 6, Block.planks.blockID);
        world.setBlock(xCoord + 6, yCoord + 0, zCoord + 5, Block.planks.blockID);
        world.setBlock(xCoord + 6, yCoord + 0, zCoord + 4, Block.planks.blockID);
        world.setBlock(xCoord + 6, yCoord + 0, zCoord + 3, Block.planks.blockID);
        world.setBlock(xCoord + 6, yCoord + 0, zCoord + 2, Block.planks.blockID);
        world.setBlock(xCoord + 6, yCoord + 0, zCoord + 1, Block.cobblestone.blockID);
        world.setBlock(xCoord + 7, yCoord + 0, zCoord + 9, Block.cobblestone.blockID);
        world.setBlock(xCoord + 7, yCoord + 0, zCoord + 8, Block.planks.blockID);
        world.setBlock(xCoord + 7, yCoord + 0, zCoord + 7, Block.planks.blockID);
        world.setBlock(xCoord + 7, yCoord + 0, zCoord + 6, Block.planks.blockID);
        world.setBlock(xCoord + 7, yCoord + 0, zCoord + 5, Block.planks.blockID);
        world.setBlock(xCoord + 7, yCoord + 0, zCoord + 4, Block.planks.blockID);
        world.setBlock(xCoord + 7, yCoord + 0, zCoord + 3, Block.planks.blockID);
        world.setBlock(xCoord + 7, yCoord + 0, zCoord + 2, Block.planks.blockID);
        world.setBlock(xCoord + 7, yCoord + 0, zCoord + 1, Block.cobblestone.blockID);
        world.setBlock(xCoord + 8, yCoord + 0, zCoord + 9, Block.cobblestone.blockID);
        world.setBlock(xCoord + 8, yCoord + 0, zCoord + 8, Block.planks.blockID);
        world.setBlock(xCoord + 8, yCoord + 0, zCoord + 7, Block.planks.blockID);
        world.setBlock(xCoord + 8, yCoord + 0, zCoord + 6, Block.planks.blockID);
        world.setBlock(xCoord + 8, yCoord + 0, zCoord + 5, Block.planks.blockID);
        world.setBlock(xCoord + 8, yCoord + 0, zCoord + 4, Block.planks.blockID);
        world.setBlock(xCoord + 8, yCoord + 0, zCoord + 3, Block.planks.blockID);
        world.setBlock(xCoord + 8, yCoord + 0, zCoord + 2, Block.planks.blockID);
        world.setBlock(xCoord + 8, yCoord + 0, zCoord + 1, Block.cobblestone.blockID);
        world.setBlock(xCoord + 9, yCoord + 0, zCoord + 9, Block.cobblestone.blockID);
        world.setBlock(xCoord + 9, yCoord + 0, zCoord + 8, Block.cobblestone.blockID);
        world.setBlock(xCoord + 9, yCoord + 0, zCoord + 7, Block.cobblestone.blockID);
        world.setBlock(xCoord + 9, yCoord + 0, zCoord + 6, Block.cobblestone.blockID);
        world.setBlock(xCoord + 9, yCoord + 0, zCoord + 5, Block.cobblestone.blockID);
        world.setBlock(xCoord + 9, yCoord + 0, zCoord + 4, Block.cobblestone.blockID);
        world.setBlock(xCoord + 9, yCoord + 0, zCoord + 3, Block.cobblestone.blockID);
        world.setBlock(xCoord + 9, yCoord + 0, zCoord + 2, Block.cobblestone.blockID);
        world.setBlock(xCoord + 9, yCoord + 0, zCoord + 1, Block.cobblestone.blockID);
        world.setBlock(xCoord + 1, yCoord + 1, zCoord + 9, Block.wood.blockID);
        world.setBlock(xCoord + 1, yCoord + 1, zCoord + 8, Block.planks.blockID);
        world.setBlock(xCoord + 1, yCoord + 1, zCoord + 7, Block.planks.blockID);
        world.setBlock(xCoord + 1, yCoord + 1, zCoord + 6, Block.planks.blockID);
        ItemDoor.placeDoorBlock(world, xCoord + 1, yCoord + 1, zCoord + 5, 0, Block.doorWood);
        world.setBlock(xCoord + 1, yCoord + 1, zCoord + 4, Block.planks.blockID);
        world.setBlock(xCoord + 1, yCoord + 1, zCoord + 3, Block.planks.blockID);
        world.setBlock(xCoord + 1, yCoord + 1, zCoord + 2, Block.planks.blockID);
        world.setBlock(xCoord + 1, yCoord + 1, zCoord + 1, Block.wood.blockID);
        world.setBlock(xCoord + 2, yCoord + 1, zCoord + 9, Block.planks.blockID);
        world.setBlockToAir(xCoord + 2, yCoord + 1, zCoord + 8);
        world.setBlockToAir(xCoord + 2, yCoord + 1, zCoord + 7);
        world.setBlockToAir(xCoord + 2, yCoord + 1, zCoord + 6);
        world.setBlockToAir(xCoord + 2, yCoord + 1, zCoord + 5);
        world.setBlockToAir(xCoord + 2, yCoord + 1, zCoord + 4);
        world.setBlockToAir(xCoord + 2, yCoord + 1, zCoord + 3);
        world.setBlock(xCoord + 2, yCoord + 1, zCoord + 2, Block.bookShelf.blockID);
        world.setBlock(xCoord + 2, yCoord + 1, zCoord + 1, Block.planks.blockID);
        world.setBlock(xCoord + 3, yCoord + 1, zCoord + 9, Block.planks.blockID);
        world.setBlockToAir(xCoord + 3, yCoord + 1, zCoord + 8);
        world.setBlock(xCoord + 3, yCoord + 1, zCoord + 7, Block.fence.blockID);
        world.setBlockToAir(xCoord + 3, yCoord + 1, zCoord + 6);
        world.setBlockToAir(xCoord + 3, yCoord + 1, zCoord + 5);
        world.setBlockToAir(xCoord + 3, yCoord + 1, zCoord + 4);
        world.setBlockToAir(xCoord + 3, yCoord + 1, zCoord + 3);
        world.setBlock(xCoord + 3, yCoord + 1, zCoord + 2, Block.bookShelf.blockID);
        world.setBlock(xCoord + 3, yCoord + 1, zCoord + 1, Block.planks.blockID);
        world.setBlock(xCoord + 4, yCoord + 1, zCoord + 9, Block.planks.blockID);
        world.setBlockToAir(xCoord + 4, yCoord + 1, zCoord + 8);
        world.setBlockToAir(xCoord + 4, yCoord + 1, zCoord + 7);
        world.setBlockToAir(xCoord + 4, yCoord + 1, zCoord + 6);
        world.setBlockToAir(xCoord + 4, yCoord + 1, zCoord + 5);
        world.setBlockToAir(xCoord + 4, yCoord + 1, zCoord + 4);
        world.setBlockToAir(xCoord + 4, yCoord + 1, zCoord + 3);
        world.setBlock(xCoord + 4, yCoord + 1, zCoord + 2, Block.bookShelf.blockID);
        world.setBlock(xCoord + 4, yCoord + 1, zCoord + 1, Block.planks.blockID);
        world.setBlock(xCoord + 5, yCoord + 1, zCoord + 9, Block.planks.blockID);
        world.setBlockToAir(xCoord + 5, yCoord + 1, zCoord + 8);
        world.setBlockToAir(xCoord + 5, yCoord + 1, zCoord + 7);
        world.setBlockToAir(xCoord + 5, yCoord + 1, zCoord + 6);
        world.setBlockToAir(xCoord + 5, yCoord + 1, zCoord + 5);
        world.setBlockToAir(xCoord + 5, yCoord + 1, zCoord + 4);
        world.setBlockToAir(xCoord + 5, yCoord + 1, zCoord + 3);
        world.setBlock(xCoord + 5, yCoord + 1, zCoord + 2, Block.bookShelf.blockID);
        world.setBlock(xCoord + 5, yCoord + 1, zCoord + 1, Block.planks.blockID);
        world.setBlock(xCoord + 6, yCoord + 1, zCoord + 9, Block.planks.blockID);
        world.setBlockToAir(xCoord + 6, yCoord + 1, zCoord + 8);
        world.setBlock(xCoord + 6, yCoord + 1, zCoord + 7, Block.fence.blockID);
        world.setBlockToAir(xCoord + 6, yCoord + 1, zCoord + 6);
        world.setBlockToAir(xCoord + 6, yCoord + 1, zCoord + 5);
        world.setBlockToAir(xCoord + 6, yCoord + 1, zCoord + 4);
        world.setBlockToAir(xCoord + 6, yCoord + 1, zCoord + 3);
        world.setBlock(xCoord + 6, yCoord + 1, zCoord + 2, Block.bookShelf.blockID);
        world.setBlock(xCoord + 6, yCoord + 1, zCoord + 1, Block.planks.blockID);
        world.setBlock(xCoord + 7, yCoord + 1, zCoord + 9, Block.planks.blockID);
        world.setBlockToAir(xCoord + 7, yCoord + 1, zCoord + 8);
        world.setBlockToAir(xCoord + 7, yCoord + 1, zCoord + 7);
        world.setBlockToAir(xCoord + 7, yCoord + 1, zCoord + 6);
        world.setBlockToAir(xCoord + 7, yCoord + 1, zCoord + 5);
        world.setBlockToAir(xCoord + 7, yCoord + 1, zCoord + 4);
        world.setBlockToAir(xCoord + 7, yCoord + 1, zCoord + 3);
        world.setBlock(xCoord + 7, yCoord + 1, zCoord + 2, Block.bookShelf.blockID);
        world.setBlock(xCoord + 7, yCoord + 1, zCoord + 1, Block.planks.blockID);
        world.setBlock(xCoord + 8, yCoord + 1, zCoord + 9, Block.planks.blockID);
        world.setBlock(xCoord + 8, yCoord + 1, zCoord + 8, Block.bookShelf.blockID);
        world.setBlock(xCoord + 8, yCoord + 1, zCoord + 7, Block.furnaceIdle.blockID);
        world.setBlock(xCoord + 8, yCoord + 1, zCoord + 6, Block.furnaceIdle.blockID);

        int chest = Blocks.chestLoot.blockID;
        int lootType = rand.nextInt(Block.cobblestone.blockID);
        int itemlocation = rand.nextInt(27);
        int numofcontents = rand.nextInt(10);

        world.setBlock(xCoord + 8, yCoord + 1, zCoord + 5, chest);
        TileEntity tileentitychest = world.getBlockTileEntity(xCoord + 8, yCoord + 1, zCoord + Block.planks.blockID);
        if (tileentitychest != null)
        {
            WeightedRandomChestContent.generateChestContents(rand, LootManager.loot, (TileEntityChest) tileentitychest, rand.nextInt(5) + 1);
        }
        ChatHandler.logDebug("Day Z House Chest Created At " + (xCoord + 8) + ", " + (yCoord + 1) + ", " + (zCoord + 5) + ".");

        world.setBlock(xCoord + 8, yCoord + 1, zCoord + 4, Block.workbench.blockID);
        world.setBlockToAir(xCoord + 8, yCoord + 1, zCoord + 3);
        world.setBlock(xCoord + 8, yCoord + 1, zCoord + 2, Block.bookShelf.blockID);
        world.setBlock(xCoord + 8, yCoord + 1, zCoord + 1, Block.planks.blockID);
        world.setBlock(xCoord + 9, yCoord + 1, zCoord + 9, Block.wood.blockID);
        world.setBlock(xCoord + 9, yCoord + 1, zCoord + 8, Block.planks.blockID);
        world.setBlock(xCoord + 9, yCoord + 1, zCoord + 7, Block.planks.blockID);
        world.setBlock(xCoord + 9, yCoord + 1, zCoord + 6, Block.planks.blockID);
        world.setBlock(xCoord + 9, yCoord + 1, zCoord + 5, Block.planks.blockID);
        world.setBlock(xCoord + 9, yCoord + 1, zCoord + 4, Block.planks.blockID);
        world.setBlock(xCoord + 9, yCoord + 1, zCoord + 3, Block.planks.blockID);
        world.setBlock(xCoord + 9, yCoord + 1, zCoord + 2, Block.planks.blockID);
        world.setBlock(xCoord + 9, yCoord + 1, zCoord + 1, Block.wood.blockID);
        world.setBlock(xCoord + 1, yCoord + 2, zCoord + 9, Block.wood.blockID);
        world.setBlock(xCoord + 1, yCoord + 2, zCoord + 8, Block.thinGlass.blockID);
        world.setBlock(xCoord + 1, yCoord + 2, zCoord + 7, Block.thinGlass.blockID);
        world.setBlock(xCoord + 1, yCoord + 2, zCoord + 6, Block.planks.blockID);
        world.setBlock(xCoord + 1, yCoord + 2, zCoord + 4, Block.planks.blockID);
        world.setBlock(xCoord + 1, yCoord + 2, zCoord + 3, Block.thinGlass.blockID);
        world.setBlock(xCoord + 1, yCoord + 2, zCoord + 2, Block.thinGlass.blockID);
        world.setBlock(xCoord + 1, yCoord + 2, zCoord + 1, Block.wood.blockID);
        world.setBlock(xCoord + 2, yCoord + 2, zCoord + 9, Block.planks.blockID);
        world.setBlockToAir(xCoord + 2, yCoord + 2, zCoord + 8);
        world.setBlockToAir(xCoord + 2, yCoord + 2, zCoord + 7);
        world.setBlockToAir(xCoord + 2, yCoord + 2, zCoord + 6);
        world.setBlockToAir(xCoord + 2, yCoord + 2, zCoord + 5);
        world.setBlockToAir(xCoord + 2, yCoord + 2, zCoord + 4);
        world.setBlockToAir(xCoord + 2, yCoord + 2, zCoord + 3);
        world.setBlock(xCoord + 2, yCoord + 2, zCoord + 2, Block.bookShelf.blockID);
        world.setBlock(xCoord + 2, yCoord + 2, zCoord + 1, Block.planks.blockID);
        world.setBlock(xCoord + 3, yCoord + 2, zCoord + 9, Block.thinGlass.blockID);
        world.setBlockToAir(xCoord + 3, yCoord + 2, zCoord + 8);
        world.setBlock(xCoord + 3, yCoord + 2, zCoord + 7, Block.pressurePlatePlanks.blockID);
        world.setBlockToAir(xCoord + 3, yCoord + 2, zCoord + 6);
        world.setBlockToAir(xCoord + 3, yCoord + 2, zCoord + 5);
        world.setBlockToAir(xCoord + 3, yCoord + 2, zCoord + 4);
        world.setBlockToAir(xCoord + 3, yCoord + 2, zCoord + 3);
        world.setBlockToAir(xCoord + 3, yCoord + 2, zCoord + 2);
        world.setBlock(xCoord + 3, yCoord + 2, zCoord + 1, Block.thinGlass.blockID);
        world.setBlock(xCoord + 4, yCoord + 2, zCoord + 9, Block.thinGlass.blockID);
        world.setBlockToAir(xCoord + 4, yCoord + 2, zCoord + 8);
        world.setBlockToAir(xCoord + 4, yCoord + 2, zCoord + 7);
        world.setBlockToAir(xCoord + 4, yCoord + 2, zCoord + 6);
        world.setBlockToAir(xCoord + 4, yCoord + 2, zCoord + 5);
        world.setBlockToAir(xCoord + 4, yCoord + 2, zCoord + 4);
        world.setBlockToAir(xCoord + 4, yCoord + 2, zCoord + 3);
        world.setBlockToAir(xCoord + 4, yCoord + 2, zCoord + 2);
        world.setBlock(xCoord + 4, yCoord + 2, zCoord + 1, Block.thinGlass.blockID);
        world.setBlock(xCoord + 5, yCoord + 2, zCoord + 10, Block.torchWood.blockID);
        world.setBlock(xCoord + 5, yCoord + 2, zCoord + 9, Block.planks.blockID);
        world.setBlock(xCoord + 5, yCoord + 2, zCoord + 8, Block.torchWood.blockID);
        world.setBlockToAir(xCoord + 5, yCoord + 2, zCoord + 7);
        world.setBlockToAir(xCoord + 5, yCoord + 2, zCoord + 6);
        world.setBlockToAir(xCoord + 5, yCoord + 2, zCoord + 5);
        world.setBlockToAir(xCoord + 5, yCoord + 2, zCoord + 4);
        world.setBlockToAir(xCoord + 5, yCoord + 2, zCoord + 3);
        world.setBlock(xCoord + 5, yCoord + 2, zCoord + 2, Block.torchWood.blockID);
        world.setBlock(xCoord + 5, yCoord + 2, zCoord + 1, Block.planks.blockID);
        world.setBlock(xCoord + 5, yCoord + 2, zCoord + 0, Block.torchWood.blockID);
        world.setBlock(xCoord + 6, yCoord + 2, zCoord + 9, Block.thinGlass.blockID);
        world.setBlockToAir(xCoord + 6, yCoord + 2, zCoord + 8);
        world.setBlock(xCoord + 6, yCoord + 2, zCoord + 7, Block.pressurePlatePlanks.blockID);
        world.setBlockToAir(xCoord + 6, yCoord + 2, zCoord + 6);
        world.setBlockToAir(xCoord + 6, yCoord + 2, zCoord + 5);
        world.setBlockToAir(xCoord + 6, yCoord + 2, zCoord + 4);
        world.setBlockToAir(xCoord + 6, yCoord + 2, zCoord + 3);
        world.setBlockToAir(xCoord + 6, yCoord + 2, zCoord + 2);
        world.setBlock(xCoord + 6, yCoord + 2, zCoord + 1, Block.thinGlass.blockID);
        world.setBlock(xCoord + 7, yCoord + 2, zCoord + 9, Block.thinGlass.blockID);
        world.setBlockToAir(xCoord + 7, yCoord + 2, zCoord + 8);
        world.setBlockToAir(xCoord + 7, yCoord + 2, zCoord + 7);
        world.setBlockToAir(xCoord + 7, yCoord + 2, zCoord + 6);
        world.setBlockToAir(xCoord + 7, yCoord + 2, zCoord + 5);
        world.setBlockToAir(xCoord + 7, yCoord + 2, zCoord + 4);
        world.setBlockToAir(xCoord + 7, yCoord + 2, zCoord + 3);
        world.setBlockToAir(xCoord + 7, yCoord + 2, zCoord + 2);
        world.setBlock(xCoord + 7, yCoord + 2, zCoord + 1, Block.thinGlass.blockID);
        world.setBlock(xCoord + 8, yCoord + 2, zCoord + 9, Block.planks.blockID);
        world.setBlock(xCoord + 8, yCoord + 2, zCoord + 8, Block.bookShelf.blockID);
        world.setBlockToAir(xCoord + 8, yCoord + 2, zCoord + 7);
        world.setBlockToAir(xCoord + 8, yCoord + 2, zCoord + 6);
        world.setBlockToAir(xCoord + 8, yCoord + 2, zCoord + 5);
        world.setBlockToAir(xCoord + 8, yCoord + 2, zCoord + 4);
        world.setBlockToAir(xCoord + 8, yCoord + 2, zCoord + 3);
        world.setBlock(xCoord + 8, yCoord + 2, zCoord + 2, Block.bookShelf.blockID);
        world.setBlock(xCoord + 8, yCoord + 2, zCoord + 1, Block.planks.blockID);
        world.setBlock(xCoord + 9, yCoord + 2, zCoord + 9, Block.wood.blockID);
        world.setBlock(xCoord + 9, yCoord + 2, zCoord + 8, Block.planks.blockID);
        world.setBlock(xCoord + 9, yCoord + 2, zCoord + 7, Block.thinGlass.blockID);
        world.setBlock(xCoord + 9, yCoord + 2, zCoord + 6, Block.thinGlass.blockID);
        world.setBlock(xCoord + 9, yCoord + 2, zCoord + 5, Block.planks.blockID);
        world.setBlock(xCoord + 9, yCoord + 2, zCoord + 4, Block.thinGlass.blockID);
        world.setBlock(xCoord + 9, yCoord + 2, zCoord + 3, Block.thinGlass.blockID);
        world.setBlock(xCoord + 9, yCoord + 2, zCoord + 2, Block.planks.blockID);
        world.setBlock(xCoord + 9, yCoord + 2, zCoord + 1, Block.wood.blockID);
        world.setBlock(xCoord + 10, yCoord + 2, zCoord + 5, Block.torchWood.blockID);
        world.setBlock(xCoord + 0, yCoord + 3, zCoord + 5, Block.torchWood.blockID);
        world.setBlock(xCoord + 1, yCoord + 3, zCoord + 10, Block.cobblestone.blockID);
        world.setBlock(xCoord + 1, yCoord + 3, zCoord + 9, Block.wood.blockID);
        world.setBlock(xCoord + 1, yCoord + 3, zCoord + 8, Block.planks.blockID);
        world.setBlock(xCoord + 1, yCoord + 3, zCoord + 7, Block.planks.blockID);
        world.setBlock(xCoord + 1, yCoord + 3, zCoord + 6, Block.planks.blockID);
        world.setBlock(xCoord + 1, yCoord + 3, zCoord + 5, Block.planks.blockID);
        world.setBlock(xCoord + 1, yCoord + 3, zCoord + 4, Block.planks.blockID);
        world.setBlock(xCoord + 1, yCoord + 3, zCoord + 3, Block.planks.blockID);
        world.setBlock(xCoord + 1, yCoord + 3, zCoord + 2, Block.planks.blockID);
        world.setBlock(xCoord + 1, yCoord + 3, zCoord + 1, Block.wood.blockID);
        world.setBlock(xCoord + 1, yCoord + 3, zCoord + 0, Block.cobblestone.blockID);
        world.setBlock(xCoord + 2, yCoord + 3, zCoord + 10, Block.cobblestone.blockID);
        world.setBlock(xCoord + 2, yCoord + 3, zCoord + 9, Block.planks.blockID);
        world.setBlockToAir(xCoord + 2, yCoord + 3, zCoord + 8);
        world.setBlock(xCoord + 2, yCoord + 3, zCoord + 7, Block.torchWood.blockID);
        world.setBlockToAir(xCoord + 2, yCoord + 3, zCoord + 6);
        world.setBlockToAir(xCoord + 2, yCoord + 3, zCoord + 5);
        world.setBlock(xCoord + 2, yCoord + 3, zCoord + 4, Block.torchWood.blockID);
        world.setBlockToAir(xCoord + 2, yCoord + 3, zCoord + 3);
        world.setBlock(xCoord + 2, yCoord + 3, zCoord + 2, Block.bookShelf.blockID);
        world.setBlock(xCoord + 2, yCoord + 3, zCoord + 1, Block.planks.blockID);
        world.setBlock(xCoord + 2, yCoord + 3, zCoord + 0, Block.cobblestone.blockID);
        world.setBlock(xCoord + 3, yCoord + 3, zCoord + 10, Block.cobblestone.blockID);
        world.setBlock(xCoord + 3, yCoord + 3, zCoord + 9, Block.planks.blockID);
        world.setBlockToAir(xCoord + 3, yCoord + 3, zCoord + 8);
        world.setBlockToAir(xCoord + 3, yCoord + 3, zCoord + 7);
        world.setBlockToAir(xCoord + 3, yCoord + 3, zCoord + 6);
        world.setBlockToAir(xCoord + 3, yCoord + 3, zCoord + 5);
        world.setBlockToAir(xCoord + 3, yCoord + 3, zCoord + 4);
        world.setBlockToAir(xCoord + 3, yCoord + 3, zCoord + 3);
        world.setBlockToAir(xCoord + 3, yCoord + 3, zCoord + 2);
        world.setBlock(xCoord + 3, yCoord + 3, zCoord + 1, Block.planks.blockID);
        world.setBlock(xCoord + 3, yCoord + 3, zCoord + 0, Block.cobblestone.blockID);
        world.setBlock(xCoord + 4, yCoord + 3, zCoord + 10, Block.cobblestone.blockID);
        world.setBlock(xCoord + 4, yCoord + 3, zCoord + 9, Block.planks.blockID);
        world.setBlockToAir(xCoord + 4, yCoord + 3, zCoord + 8);
        world.setBlockToAir(xCoord + 4, yCoord + 3, zCoord + 7);
        world.setBlockToAir(xCoord + 4, yCoord + 3, zCoord + 6);
        world.setBlockToAir(xCoord + 4, yCoord + 3, zCoord + 5);
        world.setBlockToAir(xCoord + 4, yCoord + 3, zCoord + 4);
        world.setBlockToAir(xCoord + 4, yCoord + 3, zCoord + 3);
        world.setBlockToAir(xCoord + 4, yCoord + 3, zCoord + 2);
        world.setBlock(xCoord + 4, yCoord + 3, zCoord + 1, Block.planks.blockID);
        world.setBlock(xCoord + 4, yCoord + 3, zCoord + 0, Block.cobblestone.blockID);
        world.setBlock(xCoord + 5, yCoord + 3, zCoord + 10, Block.cobblestone.blockID);
        world.setBlock(xCoord + 5, yCoord + 3, zCoord + 9, Block.planks.blockID);
        world.setBlockToAir(xCoord + 5, yCoord + 3, zCoord + 8);
        world.setBlockToAir(xCoord + 5, yCoord + 3, zCoord + 7);
        world.setBlockToAir(xCoord + 5, yCoord + 3, zCoord + 6);
        world.setBlockToAir(xCoord + 5, yCoord + 3, zCoord + 5);
        world.setBlockToAir(xCoord + 5, yCoord + 3, zCoord + 4);
        world.setBlockToAir(xCoord + 5, yCoord + 3, zCoord + 3);
        world.setBlockToAir(xCoord + 5, yCoord + 3, zCoord + 2);
        world.setBlock(xCoord + 5, yCoord + 3, zCoord + 1, Block.planks.blockID);
        world.setBlock(xCoord + 5, yCoord + 3, zCoord + 0, Block.cobblestone.blockID);
        world.setBlock(xCoord + 6, yCoord + 3, zCoord + 10, Block.cobblestone.blockID);
        world.setBlock(xCoord + 6, yCoord + 3, zCoord + 9, Block.planks.blockID);
        world.setBlockToAir(xCoord + 6, yCoord + 3, zCoord + 8);
        world.setBlockToAir(xCoord + 6, yCoord + 3, zCoord + 7);
        world.setBlockToAir(xCoord + 6, yCoord + 3, zCoord + 6);
        world.setBlockToAir(xCoord + 6, yCoord + 3, zCoord + 5);
        world.setBlockToAir(xCoord + 6, yCoord + 3, zCoord + 4);
        world.setBlockToAir(xCoord + 6, yCoord + 3, zCoord + 3);
        world.setBlockToAir(xCoord + 6, yCoord + 3, zCoord + 2);
        world.setBlock(xCoord + 6, yCoord + 3, zCoord + 1, Block.planks.blockID);
        world.setBlock(xCoord + 6, yCoord + 3, zCoord + 0, Block.cobblestone.blockID);
        world.setBlock(xCoord + 7, yCoord + 3, zCoord + 10, Block.cobblestone.blockID);
        world.setBlock(xCoord + 7, yCoord + 3, zCoord + 9, Block.planks.blockID);
        world.setBlockToAir(xCoord + 7, yCoord + 3, zCoord + 8);
        world.setBlockToAir(xCoord + 7, yCoord + 3, zCoord + 7);
        world.setBlockToAir(xCoord + 7, yCoord + 3, zCoord + 6);
        world.setBlockToAir(xCoord + 7, yCoord + 3, zCoord + 5);
        world.setBlockToAir(xCoord + 7, yCoord + 3, zCoord + 4);
        world.setBlockToAir(xCoord + 7, yCoord + 3, zCoord + 3);
        world.setBlockToAir(xCoord + 7, yCoord + 3, zCoord + 2);
        world.setBlock(xCoord + 7, yCoord + 3, zCoord + 1, Block.planks.blockID);
        world.setBlock(xCoord + 7, yCoord + 3, zCoord + 0, Block.cobblestone.blockID);
        world.setBlock(xCoord + 8, yCoord + 3, zCoord + 10, Block.cobblestone.blockID);
        world.setBlock(xCoord + 8, yCoord + 3, zCoord + 9, Block.planks.blockID);
        world.setBlockToAir(xCoord + 8, yCoord + 3, zCoord + 8);
        world.setBlock(xCoord + 8, yCoord + 3, zCoord + 7, Block.torchWood.blockID);
        world.setBlockToAir(xCoord + 8, yCoord + 3, zCoord + 6);
        world.setBlockToAir(xCoord + 8, yCoord + 3, zCoord + 5);
        world.setBlock(xCoord + 8, yCoord + 3, zCoord + 4, Block.torchWood.blockID);
        world.setBlockToAir(xCoord + 8, yCoord + 3, zCoord + 3);
        world.setBlock(xCoord + 8, yCoord + 3, zCoord + 2, Block.bookShelf.blockID);
        world.setBlock(xCoord + 8, yCoord + 3, zCoord + 1, Block.planks.blockID);
        world.setBlock(xCoord + 8, yCoord + 3, zCoord + 0, Block.cobblestone.blockID);
        world.setBlock(xCoord + 9, yCoord + 3, zCoord + 10, Block.cobblestone.blockID);
        world.setBlock(xCoord + 9, yCoord + 3, zCoord + 9, Block.wood.blockID);
        world.setBlock(xCoord + 9, yCoord + 3, zCoord + 8, Block.planks.blockID);
        world.setBlock(xCoord + 9, yCoord + 3, zCoord + 7, Block.planks.blockID);
        world.setBlock(xCoord + 9, yCoord + 3, zCoord + 6, Block.planks.blockID);
        world.setBlock(xCoord + 9, yCoord + 3, zCoord + 5, Block.planks.blockID);
        world.setBlock(xCoord + 9, yCoord + 3, zCoord + 4, Block.planks.blockID);
        world.setBlock(xCoord + 9, yCoord + 3, zCoord + 3, Block.planks.blockID);
        world.setBlock(xCoord + 9, yCoord + 3, zCoord + 2, Block.planks.blockID);
        world.setBlock(xCoord + 9, yCoord + 3, zCoord + 1, Block.wood.blockID);
        world.setBlock(xCoord + 9, yCoord + 3, zCoord + 0, Block.cobblestone.blockID);
        world.setBlock(xCoord + 1, yCoord + 4, zCoord + 9, Block.cobblestone.blockID);
        world.setBlock(xCoord + 1, yCoord + 4, zCoord + 8, Block.wood.blockID);
        world.setBlock(xCoord + 1, yCoord + 4, zCoord + 7, Block.planks.blockID);
        world.setBlock(xCoord + 1, yCoord + 4, zCoord + 6, Block.thinGlass.blockID);
        world.setBlock(xCoord + 1, yCoord + 4, zCoord + 5, Block.thinGlass.blockID);
        world.setBlock(xCoord + 1, yCoord + 4, zCoord + 4, Block.thinGlass.blockID);
        world.setBlock(xCoord + 1, yCoord + 4, zCoord + 3, Block.planks.blockID);
        world.setBlock(xCoord + 1, yCoord + 4, zCoord + 2, Block.wood.blockID);
        world.setBlock(xCoord + 1, yCoord + 4, zCoord + 1, Block.cobblestone.blockID);
        world.setBlock(xCoord + 2, yCoord + 4, zCoord + 9, Block.cobblestone.blockID);
        world.setBlockToAir(xCoord + 2, yCoord + 4, zCoord + 8);
        world.setBlockToAir(xCoord + 2, yCoord + 4, zCoord + 7);
        world.setBlockToAir(xCoord + 2, yCoord + 4, zCoord + 6);
        world.setBlockToAir(xCoord + 2, yCoord + 4, zCoord + 5);
        world.setBlockToAir(xCoord + 2, yCoord + 4, zCoord + 4);
        world.setBlockToAir(xCoord + 2, yCoord + 4, zCoord + 3);
        world.setBlockToAir(xCoord + 2, yCoord + 4, zCoord + 2);
        world.setBlock(xCoord + 2, yCoord + 4, zCoord + 1, Block.cobblestone.blockID);
        world.setBlock(xCoord + 3, yCoord + 4, zCoord + 9, Block.cobblestone.blockID);
        world.setBlockToAir(xCoord + 3, yCoord + 4, zCoord + 8);
        world.setBlockToAir(xCoord + 3, yCoord + 4, zCoord + 7);
        world.setBlockToAir(xCoord + 3, yCoord + 4, zCoord + 6);
        world.setBlockToAir(xCoord + 3, yCoord + 4, zCoord + 5);
        world.setBlockToAir(xCoord + 3, yCoord + 4, zCoord + 4);
        world.setBlockToAir(xCoord + 3, yCoord + 4, zCoord + 3);
        world.setBlockToAir(xCoord + 3, yCoord + 4, zCoord + 2);
        world.setBlock(xCoord + 3, yCoord + 4, zCoord + 1, Block.cobblestone.blockID);
        world.setBlock(xCoord + 4, yCoord + 4, zCoord + 9, Block.cobblestone.blockID);
        world.setBlockToAir(xCoord + 4, yCoord + 4, zCoord + 8);
        world.setBlockToAir(xCoord + 4, yCoord + 4, zCoord + 7);
        world.setBlockToAir(xCoord + 4, yCoord + 4, zCoord + 6);
        world.setBlockToAir(xCoord + 4, yCoord + 4, zCoord + 5);
        world.setBlockToAir(xCoord + 4, yCoord + 4, zCoord + 4);
        world.setBlockToAir(xCoord + 4, yCoord + 4, zCoord + 3);
        world.setBlockToAir(xCoord + 4, yCoord + 4, zCoord + 2);
        world.setBlock(xCoord + 4, yCoord + 4, zCoord + 1, Block.cobblestone.blockID);
        world.setBlock(xCoord + 5, yCoord + 4, zCoord + 9, Block.cobblestone.blockID);
        world.setBlockToAir(xCoord + 5, yCoord + 4, zCoord + 8);
        world.setBlockToAir(xCoord + 5, yCoord + 4, zCoord + 7);
        world.setBlockToAir(xCoord + 5, yCoord + 4, zCoord + 6);
        world.setBlockToAir(xCoord + 5, yCoord + 4, zCoord + 5);
        world.setBlockToAir(xCoord + 5, yCoord + 4, zCoord + 4);
        world.setBlockToAir(xCoord + 5, yCoord + 4, zCoord + 3);
        world.setBlockToAir(xCoord + 5, yCoord + 4, zCoord + 2);
        world.setBlock(xCoord + 5, yCoord + 4, zCoord + 1, Block.cobblestone.blockID);
        world.setBlock(xCoord + 6, yCoord + 4, zCoord + 9, Block.cobblestone.blockID);
        world.setBlockToAir(xCoord + 6, yCoord + 4, zCoord + 8);
        world.setBlockToAir(xCoord + 6, yCoord + 4, zCoord + 7);
        world.setBlockToAir(xCoord + 6, yCoord + 4, zCoord + 6);
        world.setBlockToAir(xCoord + 6, yCoord + 4, zCoord + 5);
        world.setBlockToAir(xCoord + 6, yCoord + 4, zCoord + 4);
        world.setBlockToAir(xCoord + 6, yCoord + 4, zCoord + 3);
        world.setBlockToAir(xCoord + 6, yCoord + 4, zCoord + 2);
        world.setBlock(xCoord + 6, yCoord + 4, zCoord + 1, Block.cobblestone.blockID);
        world.setBlock(xCoord + 7, yCoord + 4, zCoord + 9, Block.cobblestone.blockID);
        world.setBlockToAir(xCoord + 7, yCoord + 4, zCoord + 8);
        world.setBlockToAir(xCoord + 7, yCoord + 4, zCoord + 7);
        world.setBlockToAir(xCoord + 7, yCoord + 4, zCoord + 6);
        world.setBlockToAir(xCoord + 7, yCoord + 4, zCoord + 5);
        world.setBlockToAir(xCoord + 7, yCoord + 4, zCoord + 4);
        world.setBlockToAir(xCoord + 7, yCoord + 4, zCoord + 3);
        world.setBlockToAir(xCoord + 7, yCoord + 4, zCoord + 2);
        world.setBlock(xCoord + 7, yCoord + 4, zCoord + 1, Block.cobblestone.blockID);
        world.setBlock(xCoord + 8, yCoord + 4, zCoord + 9, Block.cobblestone.blockID);
        world.setBlockToAir(xCoord + 8, yCoord + 4, zCoord + 8);
        world.setBlockToAir(xCoord + 8, yCoord + 4, zCoord + 7);
        world.setBlockToAir(xCoord + 8, yCoord + 4, zCoord + 6);
        world.setBlockToAir(xCoord + 8, yCoord + 4, zCoord + 5);
        world.setBlockToAir(xCoord + 8, yCoord + 4, zCoord + 4);
        world.setBlockToAir(xCoord + 8, yCoord + 4, zCoord + 3);
        world.setBlockToAir(xCoord + 8, yCoord + 4, zCoord + 2);
        world.setBlock(xCoord + 8, yCoord + 4, zCoord + 1, Block.cobblestone.blockID);
        world.setBlock(xCoord + 9, yCoord + 4, zCoord + 9, Block.cobblestone.blockID);
        world.setBlock(xCoord + 9, yCoord + 4, zCoord + 8, Block.wood.blockID);
        world.setBlock(xCoord + 9, yCoord + 4, zCoord + 7, Block.planks.blockID);
        world.setBlock(xCoord + 9, yCoord + 4, zCoord + 6, Block.thinGlass.blockID);
        world.setBlock(xCoord + 9, yCoord + 4, zCoord + 5, Block.thinGlass.blockID);
        world.setBlock(xCoord + 9, yCoord + 4, zCoord + 4, Block.thinGlass.blockID);
        world.setBlock(xCoord + 9, yCoord + 4, zCoord + 3, Block.planks.blockID);
        world.setBlock(xCoord + 9, yCoord + 4, zCoord + 2, Block.wood.blockID);
        world.setBlock(xCoord + 9, yCoord + 4, zCoord + 1, Block.cobblestone.blockID);
        world.setBlock(xCoord + 1, yCoord + 5, zCoord + 8, Block.cobblestone.blockID);
        world.setBlock(xCoord + 1, yCoord + 5, zCoord + 7, Block.wood.blockID);
        world.setBlock(xCoord + 1, yCoord + 5, zCoord + 6, Block.planks.blockID);
        world.setBlock(xCoord + 1, yCoord + 5, zCoord + 5, Block.thinGlass.blockID);
        world.setBlock(xCoord + 1, yCoord + 5, zCoord + 4, Block.planks.blockID);
        world.setBlock(xCoord + 1, yCoord + 5, zCoord + 3, Block.wood.blockID);
        world.setBlock(xCoord + 1, yCoord + 5, zCoord + 2, Block.cobblestone.blockID);
        world.setBlock(xCoord + 2, yCoord + 5, zCoord + 8, Block.cobblestone.blockID);
        world.setBlockToAir(xCoord + 2, yCoord + 5, zCoord + 7);
        world.setBlockToAir(xCoord + 2, yCoord + 5, zCoord + 6);
        world.setBlockToAir(xCoord + 2, yCoord + 5, zCoord + 5);
        world.setBlockToAir(xCoord + 2, yCoord + 5, zCoord + 4);
        world.setBlockToAir(xCoord + 2, yCoord + 5, zCoord + 3);
        world.setBlock(xCoord + 2, yCoord + 5, zCoord + 2, Block.cobblestone.blockID);
        world.setBlock(xCoord + 3, yCoord + 5, zCoord + 8, Block.cobblestone.blockID);
        world.setBlockToAir(xCoord + 3, yCoord + 5, zCoord + 7);
        world.setBlockToAir(xCoord + 3, yCoord + 5, zCoord + 6);
        world.setBlockToAir(xCoord + 3, yCoord + 5, zCoord + 5);
        world.setBlockToAir(xCoord + 3, yCoord + 5, zCoord + 4);
        world.setBlockToAir(xCoord + 3, yCoord + 5, zCoord + 3);
        world.setBlock(xCoord + 3, yCoord + 5, zCoord + 2, Block.cobblestone.blockID);
        world.setBlock(xCoord + 4, yCoord + 5, zCoord + 8, Block.cobblestone.blockID);
        world.setBlockToAir(xCoord + 4, yCoord + 5, zCoord + 7);
        world.setBlockToAir(xCoord + 4, yCoord + 5, zCoord + 6);
        world.setBlockToAir(xCoord + 4, yCoord + 5, zCoord + 5);
        world.setBlockToAir(xCoord + 4, yCoord + 5, zCoord + 4);
        world.setBlockToAir(xCoord + 4, yCoord + 5, zCoord + 3);
        world.setBlock(xCoord + 4, yCoord + 5, zCoord + 2, Block.cobblestone.blockID);
        world.setBlock(xCoord + 5, yCoord + 5, zCoord + 8, Block.cobblestone.blockID);
        world.setBlockToAir(xCoord + 5, yCoord + 5, zCoord + 7);
        world.setBlockToAir(xCoord + 5, yCoord + 5, zCoord + 6);
        world.setBlockToAir(xCoord + 5, yCoord + 5, zCoord + 5);
        world.setBlockToAir(xCoord + 5, yCoord + 5, zCoord + 4);
        world.setBlockToAir(xCoord + 5, yCoord + 5, zCoord + 3);
        world.setBlock(xCoord + 5, yCoord + 5, zCoord + 2, Block.cobblestone.blockID);
        world.setBlock(xCoord + 6, yCoord + 5, zCoord + 8, Block.cobblestone.blockID);
        world.setBlockToAir(xCoord + 6, yCoord + 5, zCoord + 7);
        world.setBlockToAir(xCoord + 6, yCoord + 5, zCoord + 6);
        world.setBlockToAir(xCoord + 6, yCoord + 5, zCoord + 5);
        world.setBlockToAir(xCoord + 6, yCoord + 5, zCoord + 4);
        world.setBlockToAir(xCoord + 6, yCoord + 5, zCoord + 3);
        world.setBlock(xCoord + 6, yCoord + 5, zCoord + 2, Block.cobblestone.blockID);
        world.setBlock(xCoord + 7, yCoord + 5, zCoord + 8, Block.cobblestone.blockID);
        world.setBlockToAir(xCoord + 7, yCoord + 5, zCoord + 7);
        world.setBlockToAir(xCoord + 7, yCoord + 5, zCoord + 6);
        world.setBlockToAir(xCoord + 7, yCoord + 5, zCoord + 5);
        world.setBlockToAir(xCoord + 7, yCoord + 5, zCoord + 4);
        world.setBlockToAir(xCoord + 7, yCoord + 5, zCoord + 3);
        world.setBlock(xCoord + 7, yCoord + 5, zCoord + 2, Block.cobblestone.blockID);
        world.setBlock(xCoord + 8, yCoord + 5, zCoord + 8, Block.cobblestone.blockID);
        world.setBlockToAir(xCoord + 8, yCoord + 5, zCoord + 7);
        world.setBlockToAir(xCoord + 8, yCoord + 5, zCoord + 6);
        world.setBlockToAir(xCoord + 8, yCoord + 5, zCoord + 5);
        world.setBlockToAir(xCoord + 8, yCoord + 5, zCoord + 4);
        world.setBlockToAir(xCoord + 8, yCoord + 5, zCoord + 3);
        world.setBlock(xCoord + 8, yCoord + 5, zCoord + 2, Block.cobblestone.blockID);
        world.setBlock(xCoord + 9, yCoord + 5, zCoord + 8, Block.cobblestone.blockID);
        world.setBlock(xCoord + 9, yCoord + 5, zCoord + 7, Block.wood.blockID);
        world.setBlock(xCoord + 9, yCoord + 5, zCoord + 6, Block.planks.blockID);
        world.setBlock(xCoord + 9, yCoord + 5, zCoord + 5, Block.thinGlass.blockID);
        world.setBlock(xCoord + 9, yCoord + 5, zCoord + 4, Block.planks.blockID);
        world.setBlock(xCoord + 9, yCoord + 5, zCoord + 3, Block.wood.blockID);
        world.setBlock(xCoord + 9, yCoord + 5, zCoord + 2, Block.cobblestone.blockID);
        world.setBlock(xCoord + 1, yCoord + 6, zCoord + 7, Block.cobblestone.blockID);
        world.setBlock(xCoord + 1, yCoord + 6, zCoord + 6, Block.wood.blockID);
        world.setBlock(xCoord + 1, yCoord + 6, zCoord + 5, Block.planks.blockID);
        world.setBlock(xCoord + 1, yCoord + 6, zCoord + 4, Block.wood.blockID);
        world.setBlock(xCoord + 1, yCoord + 6, zCoord + 3, Block.cobblestone.blockID);
        world.setBlock(xCoord + 2, yCoord + 6, zCoord + 7, Block.cobblestone.blockID);
        world.setBlockToAir(xCoord + 2, yCoord + 6, zCoord + 6);
        world.setBlockToAir(xCoord + 2, yCoord + 6, zCoord + 5);
        world.setBlockToAir(xCoord + 2, yCoord + 6, zCoord + 4);
        world.setBlock(xCoord + 2, yCoord + 6, zCoord + 3, Block.cobblestone.blockID);
        world.setBlock(xCoord + 3, yCoord + 6, zCoord + 7, Block.cobblestone.blockID);
        world.setBlockToAir(xCoord + 3, yCoord + 6, zCoord + 6);
        world.setBlockToAir(xCoord + 3, yCoord + 6, zCoord + 5);
        world.setBlockToAir(xCoord + 3, yCoord + 6, zCoord + 4);
        world.setBlock(xCoord + 3, yCoord + 6, zCoord + 3, Block.cobblestone.blockID);
        world.setBlock(xCoord + 4, yCoord + 6, zCoord + 7, Block.cobblestone.blockID);
        world.setBlockToAir(xCoord + 4, yCoord + 6, zCoord + 6);
        world.setBlockToAir(xCoord + 4, yCoord + 6, zCoord + 5);
        world.setBlockToAir(xCoord + 4, yCoord + 6, zCoord + 4);
        world.setBlock(xCoord + 4, yCoord + 6, zCoord + 3, Block.cobblestone.blockID);
        world.setBlock(xCoord + 5, yCoord + 6, zCoord + 7, Block.cobblestone.blockID);
        world.setBlockToAir(xCoord + 5, yCoord + 6, zCoord + 6);
        world.setBlockToAir(xCoord + 5, yCoord + 6, zCoord + 5);
        world.setBlockToAir(xCoord + 5, yCoord + 6, zCoord + 4);
        world.setBlock(xCoord + 5, yCoord + 6, zCoord + 3, Block.cobblestone.blockID);
        world.setBlock(xCoord + 6, yCoord + 6, zCoord + 7, Block.cobblestone.blockID);
        world.setBlockToAir(xCoord + 6, yCoord + 6, zCoord + 6);
        world.setBlockToAir(xCoord + 6, yCoord + 6, zCoord + 5);
        world.setBlockToAir(xCoord + 6, yCoord + 6, zCoord + 4);
        world.setBlock(xCoord + 6, yCoord + 6, zCoord + 3, Block.cobblestone.blockID);
        world.setBlock(xCoord + 7, yCoord + 6, zCoord + 7, Block.cobblestone.blockID);
        world.setBlockToAir(xCoord + 7, yCoord + 6, zCoord + 6);
        world.setBlockToAir(xCoord + 7, yCoord + 6, zCoord + 5);
        world.setBlockToAir(xCoord + 7, yCoord + 6, zCoord + 4);
        world.setBlock(xCoord + 7, yCoord + 6, zCoord + 3, Block.cobblestone.blockID);
        world.setBlock(xCoord + 8, yCoord + 6, zCoord + 7, Block.cobblestone.blockID);
        world.setBlockToAir(xCoord + 8, yCoord + 6, zCoord + 6);
        world.setBlockToAir(xCoord + 8, yCoord + 6, zCoord + 5);
        world.setBlockToAir(xCoord + 8, yCoord + 6, zCoord + 4);
        world.setBlock(xCoord + 8, yCoord + 6, zCoord + 3, Block.cobblestone.blockID);
        world.setBlock(xCoord + 9, yCoord + 6, zCoord + 7, Block.cobblestone.blockID);
        world.setBlock(xCoord + 9, yCoord + 6, zCoord + 6, Block.wood.blockID);
        world.setBlock(xCoord + 9, yCoord + 6, zCoord + 5, Block.planks.blockID);
        world.setBlock(xCoord + 9, yCoord + 6, zCoord + 4, Block.wood.blockID);
        world.setBlock(xCoord + 9, yCoord + 6, zCoord + 3, Block.cobblestone.blockID);
        world.setBlock(xCoord + 1, yCoord + 7, zCoord + 6, Block.cobblestone.blockID);
        world.setBlock(xCoord + 1, yCoord + 7, zCoord + 5, Block.wood.blockID);
        world.setBlock(xCoord + 1, yCoord + 7, zCoord + 4, Block.cobblestone.blockID);
        world.setBlock(xCoord + 2, yCoord + 7, zCoord + 6, Block.cobblestone.blockID);
        world.setBlockToAir(xCoord + 2, yCoord + 7, zCoord + 5);
        world.setBlock(xCoord + 2, yCoord + 7, zCoord + 4, Block.cobblestone.blockID);
        world.setBlock(xCoord + 3, yCoord + 7, zCoord + 6, Block.cobblestone.blockID);
        world.setBlockToAir(xCoord + 3, yCoord + 7, zCoord + 5);
        world.setBlock(xCoord + 3, yCoord + 7, zCoord + 4, Block.cobblestone.blockID);
        world.setBlock(xCoord + 4, yCoord + 7, zCoord + 6, Block.cobblestone.blockID);
        world.setBlockToAir(xCoord + 4, yCoord + 7, zCoord + 5);
        world.setBlock(xCoord + 4, yCoord + 7, zCoord + 4, Block.cobblestone.blockID);
        world.setBlock(xCoord + 5, yCoord + 7, zCoord + 6, Block.cobblestone.blockID);
        world.setBlockToAir(xCoord + 5, yCoord + 7, zCoord + 5);
        world.setBlock(xCoord + 5, yCoord + 7, zCoord + 4, Block.cobblestone.blockID);
        world.setBlock(xCoord + 6, yCoord + 7, zCoord + 6, Block.cobblestone.blockID);
        world.setBlockToAir(xCoord + 6, yCoord + 7, zCoord + 5);
        world.setBlock(xCoord + 6, yCoord + 7, zCoord + 4, Block.cobblestone.blockID);
        world.setBlock(xCoord + 7, yCoord + 7, zCoord + 6, Block.cobblestone.blockID);
        world.setBlockToAir(xCoord + 7, yCoord + 7, zCoord + 5);
        world.setBlock(xCoord + 7, yCoord + 7, zCoord + 4, Block.cobblestone.blockID);
        world.setBlock(xCoord + 8, yCoord + 7, zCoord + 6, Block.cobblestone.blockID);
        world.setBlockToAir(xCoord + 8, yCoord + 7, zCoord + 5);
        world.setBlock(xCoord + 8, yCoord + 7, zCoord + 4, Block.cobblestone.blockID);
        world.setBlock(xCoord + 9, yCoord + 7, zCoord + 6, Block.cobblestone.blockID);
        world.setBlock(xCoord + 9, yCoord + 7, zCoord + 5, Block.wood.blockID);
        world.setBlock(xCoord + 9, yCoord + 7, zCoord + 4, Block.cobblestone.blockID);
        world.setBlock(xCoord + 1, yCoord + 8, zCoord + 5, Block.cobblestone.blockID);
        world.setBlock(xCoord + 2, yCoord + 8, zCoord + 5, Block.cobblestone.blockID);
        world.setBlock(xCoord + 3, yCoord + 8, zCoord + 5, Block.cobblestone.blockID);
        world.setBlock(xCoord + 4, yCoord + 8, zCoord + 5, Block.cobblestone.blockID);
        world.setBlock(xCoord + 5, yCoord + 8, zCoord + 5, Block.cobblestone.blockID);
        world.setBlock(xCoord + 6, yCoord + 8, zCoord + 5, Block.cobblestone.blockID);
        world.setBlock(xCoord + 7, yCoord + 8, zCoord + 5, Block.cobblestone.blockID);
        world.setBlock(xCoord + 8, yCoord + 8, zCoord + 5, Block.cobblestone.blockID);
        world.setBlock(xCoord + 9, yCoord + 8, zCoord + 5, Block.cobblestone.blockID);
        return true;
    }
}